Workbook

Sheet CAMPIONATO
B3: ANDATA | D3: 1ª GIORNATA - 1° GIRONE | W3: RITORNO | Z3: ANDATA | AB3: 1ª GIORNATA - 2° GIRONE | AU3: RITORNO | AX3: =CONCATENATE("CLASSIFICA FANTACALCIO ",'Proposte d''Acquisto'!B1," ") -> CLASSIFICA FANTACALCIO 2018/2019
D4: ='Proposte d''Acquisto'!B3 -> ENRICO | E4: =IF(B4>C4,3,IF(B4<C4,0,IF(B4="","",1))) | F4: =IF(C4>B4,3,IF(C4<B4,0,IF(C4="","",1))) | G4: =IF(E4=3,1,0) -> 0 | H4: =IF(E4=1,1,0) -> 0 | I4: =IF(E4=0,1,0) -> 0 | J4: =IF(F4=3,1,0) -> 0 | K4: =IF(F4=1,1,0) -> 0 | L4: =IF(F4=0,1,0) -> 0 | N4: ='Proposte d''Acquisto'!B8 -> RICCARDO | O4: =IF(W4>X4,3,IF(W4<X4,0,IF(W4="","",1))) | P4: =IF(X4>W4,3,IF(X4<W4,0,IF(X4="","",1))) | Q4: =IF(O4=3,1,0) -> 0 | R4: =IF(O4=1,1,0) -> 0 | S4: =IF(O4=0,1,0) -> 0 | T4: =IF(P4=3,1,0) -> 0 | U4: =IF(P4=1,1,0) -> 0 | V4: =IF(P4=0,1,0) -> 0 | AB4: ='Proposte d''Acquisto'!B3 -> ENRICO | AC4: =IF(Z4>AA4,3,IF(Z4<AA4,0,IF(Z4="","",1))) | AD4: =IF(AA4>Z4,3,IF(AA4<Z4,0,IF(AA4="","",1))) | AE4: =IF(AC4=3,1,0) -> 0 | AF4: =IF(AC4=1,1,0) -> 0 | AG4: =IF(AC4=0,1,0) -> 0 | AH4: =IF(AD4=3,1,0) -> 0 | AI4: =IF(AD4=1,1,0) -> 0 | AJ4: =IF(AD4=0,1,0) -> 0 | AL4: ='Proposte d''Acquisto'!B8 -> RICCARDO | AM4: =IF(AU4>AV4,3,IF(AU4<AV4,0,IF(AU4="","",1))) | AN4: =IF(AV4>AU4,3,IF(AV4<AU4,0,IF(AV4="","",1))) | AO4: =IF(AM4=3,1,0) -> 0 | AP4: =IF(AM4=1,1,0) -> 0 | AQ4: =IF(AM4=0,1,0) -> 0 | AR4: =IF(AN4=3,1,0) -> 0 | AS4: =IF(AN4=1,1,0) -> 0 | AT4: =IF(AN4=0,1,0) -> 0
D5: ='Proposte d''Acquisto'!B13 -> FABRIZIO | E5: =IF(B5>C5,3,IF(B5<C5,0,IF(B5="","",1))) | F5: =IF(C5>B5,3,IF(C5<B5,0,IF(C5="","",1))) | G5: =IF(E5=3,1,0) -> 0 | H5: =IF(E5=1,1,0) -> 0 | I5: =IF(E5=0,1,0) -> 0 | J5: =IF(F5=3,1,0) -> 0 | K5: =IF(F5=1,1,0) -> 0 | L5: =IF(F5=0,1,0) -> 0 | N5: ='Proposte d''Acquisto'!B38 -> DARIO | O5: =IF(W5>X5,3,IF(W5<X5,0,IF(W5="","",1))) | P5: =IF(X5>W5,3,IF(X5<W5,0,IF(X5="","",1))) | Q5: =IF(O5=3,1,0) -> 0 | R5: =IF(O5=1,1,0) -> 0 | S5: =IF(O5=0,1,0) -> 0 | T5: =IF(P5=3,1,0) -> 0 | U5: =IF(P5=1,1,0) -> 0 | V5: =IF(P5=0,1,0) -> 0 | AB5: ='Proposte d''Acquisto'!B13 -> FABRIZIO | AC5: =IF(Z5>AA5,3,IF(Z5<AA5,0,IF(Z5="","",1))) | AD5: =IF(AA5>Z5,3,IF(AA5<Z5,0,IF(AA5="","",1))) | AE5: =IF(AC5=3,1,0) -> 0 | AF5: =IF(AC5=1,1,0) -> 0 | AG5: =IF(AC5=0,1,0) -> 0 | AH5: =IF(AD5=3,1,0) -> 0 | AI5: =IF(AD5=1,1,0) -> 0 | AJ5: =IF(AD5=0,1,0) -> 0 | AL5: ='Proposte d''Acquisto'!B38 -> DARIO | AM5: =IF(AU5>AV5,3,IF(AU5<AV5,0,IF(AU5="","",1))) | AN5: =IF(AV5>AU5,3,IF(AV5<AU5,0,IF(AV5="","",1))) | AO5: =IF(AM5=3,1,0) -> 0 | AP5: =IF(AM5=1,1,0) -> 0 | AQ5: =IF(AM5=0,1,0) -> 0 | AR5: =IF(AN5=3,1,0) -> 0 | AS5: =IF(AN5=1,1,0) -> 0 | AT5: =IF(AN5=0,1,0) -> 0 | AX5: SQUADRE | AY5: PUNTI | AZ5: VITTORIE | BA5: PAREGGI | BB5: SCONFITTE | BC5: GIOCATE | BD5: GOAL FATTI | BE5: GOAL SUBITI | BF5: DIFFERENZA | BG5: DARE | BH5: SPAREGGI | BI5: PUNTEGGIO REALE | BJ5: PENALITA' | BK5: FORMULA
D6: ='Proposte d''Acquisto'!B23 -> MOLINA | E6: =IF(B6>C6,3,IF(B6<C6,0,IF(B6="","",1))) | F6: =IF(C6>B6,3,IF(C6<B6,0,IF(C6="","",1))) | G6: =IF(E6=3,1,0) -> 0 | H6: =IF(E6=1,1,0) -> 0 | I6: =IF(E6=0,1,0) -> 0 | J6: =IF(F6=3,1,0) -> 0 | K6: =IF(F6=1,1,0) -> 0 | L6: =IF(F6=0,1,0) -> 0 | N6: ='Proposte d''Acquisto'!B28 -> EUGENIO | O6: =IF(W6>X6,3,IF(W6<X6,0,IF(W6="","",1))) | P6: =IF(X6>W6,3,IF(X6<W6,0,IF(X6="","",1))) | Q6: =IF(O6=3,1,0) -> 0 | R6: =IF(O6=1,1,0) -> 0 | S6: =IF(O6=0,1,0) -> 0 | T6: =IF(P6=3,1,0) -> 0 | U6: =IF(P6=1,1,0) -> 0 | V6: =IF(P6=0,1,0) -> 0 | AB6: ='Proposte d''Acquisto'!B23 -> MOLINA | AC6: =IF(Z6>AA6,3,IF(Z6<AA6,0,IF(Z6="","",1))) | AD6: =IF(AA6>Z6,3,IF(AA6<Z6,0,IF(AA6="","",1))) | AE6: =IF(AC6=3,1,0) -> 0 | AF6: =IF(AC6=1,1,0) -> 0 | AG6: =IF(AC6=0,1,0) -> 0 | AH6: =IF(AD6=3,1,0) -> 0 | AI6: =IF(AD6=1,1,0) -> 0 | AJ6: =IF(AD6=0,1,0) -> 0 | AL6: ='Proposte d''Acquisto'!B28 -> EUGENIO | AM6: =IF(AU6>AV6,3,IF(AU6<AV6,0,IF(AU6="","",1))) | AN6: =IF(AV6>AU6,3,IF(AV6<AU6,0,IF(AV6="","",1))) | AO6: =IF(AM6=3,1,0) -> 0 | AP6: =IF(AM6=1,1,0) -> 0 | AQ6: =IF(AM6=0,1,0) -> 0 | AR6: =IF(AN6=3,1,0) -> 0 | AS6: =IF(AN6=1,1,0) -> 0 | AT6: =IF(AN6=0,1,0) -> 0 | AX6: Eugenio | AY6: =AZ6*3+BA6 -> 0 | BC6: =SUM(AZ6,BA6,BB6) -> 0 | BF6: =SUM(BD6-BE6) -> 0 | BG6: =IF(BH6="*",0,SUM(BB6*Premi!H5+BA6*Premi!H4)) -> 0 | BI6: =SUM($E$5,$O$5,$AC$5,$AM$5,$E$12,$O$12,$AC$12,$AM$12,$F$18,$P$18,$AD$18,$AN$18,$F$26,$P$26,$AD$26,$AN$26,$E$32,$O$32,$AC$32,$AM$32,$F$40,$P$40,$AD$40,$AN$40,$E$47,$O$47,$AC$47,$AM$47) -> 0 | BJ6: 0 | BK6: =(BF6*1000)+BD6 -> 0
D7: ='Proposte d''Acquisto'!B33 -> VINCENZO | E7: =IF(B7>C7,3,IF(B7<C7,0,IF(B7="","",1))) | F7: =IF(C7>B7,3,IF(C7<B7,0,IF(C7="","",1))) | G7: =IF(E7=3,1,0) -> 0 | H7: =IF(E7=1,1,0) -> 0 | I7: =IF(E7=0,1,0) -> 0 | J7: =IF(F7=3,1,0) -> 0 | K7: =IF(F7=1,1,0) -> 0 | L7: =IF(F7=0,1,0) -> 0 | N7: ='Proposte d''Acquisto'!B18 -> DANIELE | O7: =IF(W7>X7,3,IF(W7<X7,0,IF(W7="","",1))) | P7: =IF(X7>W7,3,IF(X7<W7,0,IF(X7="","",1))) | Q7: =IF(O7=3,1,0) -> 0 | R7: =IF(O7=1,1,0) -> 0 | S7: =IF(O7=0,1,0) -> 0 | T7: =IF(P7=3,1,0) -> 0 | U7: =IF(P7=1,1,0) -> 0 | V7: =IF(P7=0,1,0) -> 0 | AB7: ='Proposte d''Acquisto'!B33 -> VINCENZO | AC7: =IF(Z7>AA7,3,IF(Z7<AA7,0,IF(Z7="","",1))) | AD7: =IF(AA7>Z7,3,IF(AA7<Z7,0,IF(AA7="","",1))) | AE7: =IF(AC7=3,1,0) -> 0 | AF7: =IF(AC7=1,1,0) -> 0 | AG7: =IF(AC7=0,1,0) -> 0 | AH7: =IF(AD7=3,1,0) -> 0 | AI7: =IF(AD7=1,1,0) -> 0 | AJ7: =IF(AD7=0,1,0) -> 0 | AL7: ='Proposte d''Acquisto'!B18 -> DANIELE | AM7: =IF(AU7>AV7,3,IF(AU7<AV7,0,IF(AU7="","",1))) | AN7: =IF(AV7>AU7,3,IF(AV7<AU7,0,IF(AV7="","",1))) | AO7: =IF(AM7=3,1,0) -> 0 | AP7: =IF(AM7=1,1,0) -> 0 | AQ7: =IF(AM7=0,1,0) -> 0 | AR7: =IF(AN7=3,1,0) -> 0 | AS7: =IF(AN7=1,1,0) -> 0 | AT7: =IF(AN7=0,1,0) -> 0
AX8: Riccardo | AY8: =AZ8*3+BA8 -> 0 | BC8: =SUM(AZ8,BA8,BB8) -> 0 | BF8: =SUM(BD8-BE8) -> 0 | BG8: =IF(BH8="*",0,SUM(BB8*Premi!H5+BA8*Premi!H4)) -> 0 | BI8: =SUM($F$4,$P$4,$AD$4,$AN$4,$E$11,$O$11,$AC$11,$AM$11,$F$20,$P$20,$AD$20,$AN$20,$E$28,$O$28,$AC$28,$AM$28,$F$33,$P$33,$AD$33,$AN$33,$E$39,$O$39,$AC$39,$AM$39,$F$47,$P$47,$AD$47,$AN$47) -> 0 | BJ8: 0 | BK8: =(BF8*1000)+BD8 -> 0
B10: ANDATA | D10: 2ª GIORNATA - 1° GIRONE | W10: RITORNO | Z10: ANDATA | AB10: 2ª GIORNATA - 2° GIRONE | AU10: RITORNO | AX10: Enrico | AY10: =AZ10*3+BA10 -> 0 | BC10: =SUM(AZ10,BA10,BB10) -> 0 | BF10: =SUM(BD10-BE10) -> 0 | BG10: =IF(BH10="*",0,SUM(BB10*Premi!H5+BA10*Premi!H4)) -> 0 | BI10: =SUM($F$6,$P$6,$AD$6,$AN$6,$F$11,$P$11,$AD$11,$AN$11,$E$21,$O$21,$AC$21,$AM$21,$E$26,$O$26,$AC$26,$AM$26,$F$35,$P$35,$AD$35,$AN$35,$E$42,$O$42,$AC$42,$AM$42,$F$46,$P$46,$AD$46,$AN$46) -> 0 | BJ10: 0 | BK10: =(BF10*1000)+BD10 -> 0
D11: ='Proposte d''Acquisto'!B8 -> RICCARDO | E11: =IF(B11>C11,3,IF(B11<C11,0,IF(B11="","",1))) | F11: =IF(C11>B11,3,IF(C11<B11,0,IF(C11="","",1))) | G11: =IF(E11=3,1,0) -> 0 | H11: =IF(E11=1,1,0) -> 0 | I11: =IF(E11=0,1,0) -> 0 | J11: =IF(F11=3,1,0) -> 0 | K11: =IF(F11=1,1,0) -> 0 | L11: =IF(F11=0,1,0) -> 0 | N11: ='Proposte d''Acquisto'!B28 -> EUGENIO | O11: =IF(W11>X11,3,IF(W11<X11,0,IF(W11="","",1))) | P11: =IF(X11>W11,3,IF(X11<W11,0,IF(X11="","",1))) | Q11: =IF(O11=3,1,0) -> 0 | R11: =IF(O11=1,1,0) -> 0 | S11: =IF(O11=0,1,0) -> 0 | T11: =IF(P11=3,1,0) -> 0 | U11: =IF(P11=1,1,0) -> 0 | V11: =IF(P11=0,1,0) -> 0 | AB11: ='Proposte d''Acquisto'!B8 -> RICCARDO | AC11: =IF(Z11>AA11,3,IF(Z11<AA11,0,IF(Z11="","",1))) | AD11: =IF(AA11>Z11,3,IF(AA11<Z11,0,IF(AA11="","",1))) | AE11: =IF(AC11=3,1,0) -> 0 | AF11: =IF(AC11=1,1,0) -> 0 | AG11: =IF(AC11=0,1,0) -> 0 | AH11: =IF(AD11=3,1,0) -> 0 | AI11: =IF(AD11=1,1,0) -> 0 | AJ11: =IF(AD11=0,1,0) -> 0 | AL11: ='Proposte d''Acquisto'!B28 -> EUGENIO | AM11: =IF(AU11>AV11,3,IF(AU11<AV11,0,IF(AU11="","",1))) | AN11: =IF(AV11>AU11,3,IF(AV11<AU11,0,IF(AV11="","",1))) | AO11: =IF(AM11=3,1,0) -> 0 | AP11: =IF(AM11=1,1,0) -> 0 | AQ11: =IF(AM11=0,1,0) -> 0 | AR11: =IF(AN11=3,1,0) -> 0 | AS11: =IF(AN11=1,1,0) -> 0 | AT11: =IF(AN11=0,1,0) -> 0
D12: ='Proposte d''Acquisto'!B13 -> FABRIZIO | E12: =IF(B12>C12,3,IF(B12<C12,0,IF(B12="","",1))) | F12: =IF(C12>B12,3,IF(C12<B12,0,IF(C12="","",1))) | G12: =IF(E12=3,1,0) -> 0 | H12: =IF(E12=1,1,0) -> 0 | I12: =IF(E12=0,1,0) -> 0 | J12: =IF(F12=3,1,0) -> 0 | K12: =IF(F12=1,1,0) -> 0 | L12: =IF(F12=0,1,0) -> 0 | N12: ='Proposte d''Acquisto'!B33 -> VINCENZO | O12: =IF(W12>X12,3,IF(W12<X12,0,IF(W12="","",1))) | P12: =IF(X12>W12,3,IF(X12<W12,0,IF(X12="","",1))) | Q12: =IF(O12=3,1,0) -> 0 | R12: =IF(O12=1,1,0) -> 0 | S12: =IF(O12=0,1,0) -> 0 | T12: =IF(P12=3,1,0) -> 0 | U12: =IF(P12=1,1,0) -> 0 | V12: =IF(P12=0,1,0) -> 0 | AB12: ='Proposte d''Acquisto'!B13 -> FABRIZIO | AC12: =IF(Z12>AA12,3,IF(Z12<AA12,0,IF(Z12="","",1))) | AD12: =IF(AA12>Z12,3,IF(AA12<Z12,0,IF(AA12="","",1))) | AE12: =IF(AC12=3,1,0) -> 0 | AF12: =IF(AC12=1,1,0) -> 0 | AG12: =IF(AC12=0,1,0) -> 0 | AH12: =IF(AD12=3,1,0) -> 0 | AI12: =IF(AD12=1,1,0) -> 0 | AJ12: =IF(AD12=0,1,0) -> 0 | AL12: ='Proposte d''Acquisto'!B33 -> VINCENZO | AM12: =IF(AU12>AV12,3,IF(AU12<AV12,0,IF(AU12="","",1))) | AN12: =IF(AV12>AU12,3,IF(AV12<AU12,0,IF(AV12="","",1))) | AO12: =IF(AM12=3,1,0) -> 0 | AP12: =IF(AM12=1,1,0) -> 0 | AQ12: =IF(AM12=0,1,0) -> 0 | AR12: =IF(AN12=3,1,0) -> 0 | AS12: =IF(AN12=1,1,0) -> 0 | AT12: =IF(AN12=0,1,0) -> 0 | AX12: Vincenzo | AY12: =AZ12*3+BA12 -> 0 | BC12: =SUM(AZ12,BA12,BB12) -> 0 | BF12: =SUM(BD12-BE12) -> 0 | BG12: =IF(BH12="*",0,SUM(BB12*Premi!H5+BA12*Premi!H4)) -> 0 | BI12: =SUM($F$7,$P$7,$AD$7,$AN$7,$E$14,$O$14,$AC$14,$AM$14,$F$19,$P$19,$AD$19,$AN$19,$E$27,$O$27,$AC$27,$AM$27,$F$32,$P$32,$AD$32,$AN$32,$F$39,$P$39,$AD$39,$AN$39,$E$46,$O$46,$AC$46,$AM$46) -> 0 | BJ12: 0 | BK12: =(BF12*1000)+BD12 -> 0
D13: ='Proposte d''Acquisto'!B38 -> DARIO | E13: =IF(B13>C13,3,IF(B13<C13,0,IF(B13="","",1))) | F13: =IF(C13>B13,3,IF(C13<B13,0,IF(C13="","",1))) | G13: =IF(E13=3,1,0) -> 0 | H13: =IF(E13=1,1,0) -> 0 | I13: =IF(E13=0,1,0) -> 0 | J13: =IF(F13=3,1,0) -> 0 | K13: =IF(F13=1,1,0) -> 0 | L13: =IF(F13=0,1,0) -> 0 | N13: ='Proposte d''Acquisto'!B23 -> MOLINA | O13: =IF(W13>X13,3,IF(W13<X13,0,IF(W13="","",1))) | P13: =IF(X13>W13,3,IF(X13<W13,0,IF(X13="","",1))) | Q13: =IF(O13=3,1,0) -> 0 | R13: =IF(O13=1,1,0) -> 0 | S13: =IF(O13=0,1,0) -> 0 | T13: =IF(P13=3,1,0) -> 0 | U13: =IF(P13=1,1,0) -> 0 | V13: =IF(P13=0,1,0) -> 0 | AB13: ='Proposte d''Acquisto'!B38 -> DARIO | AC13: =IF(Z13>AA13,3,IF(Z13<AA13,0,IF(Z13="","",1))) | AD13: =IF(AA13>Z13,3,IF(AA13<Z13,0,IF(AA13="","",1))) | AE13: =IF(AC13=3,1,0) -> 0 | AF13: =IF(AC13=1,1,0) -> 0 | AG13: =IF(AC13=0,1,0) -> 0 | AH13: =IF(AD13=3,1,0) -> 0 | AI13: =IF(AD13=1,1,0) -> 0 | AJ13: =IF(AD13=0,1,0) -> 0 | AL13: ='Proposte d''Acquisto'!B23 -> MOLINA | AM13: =IF(AU13>AV13,3,IF(AU13<AV13,0,IF(AU13="","",1))) | AN13: =IF(AV13>AU13,3,IF(AV13<AU13,0,IF(AV13="","",1))) | AO13: =IF(AM13=3,1,0) -> 0 | AP13: =IF(AM13=1,1,0) -> 0 | AQ13: =IF(AM13=0,1,0) -> 0 | AR13: =IF(AN13=3,1,0) -> 0 | AS13: =IF(AN13=1,1,0) -> 0 | AT13: =IF(AN13=0,1,0) -> 0
D14: ='Proposte d''Acquisto'!B18 -> DANIELE | E14: =IF(B14>C14,3,IF(B14<C14,0,IF(B14="","",1))) | F14: =IF(C14>B14,3,IF(C14<B14,0,IF(C14="","",1))) | G14: =IF(E14=3,1,0) -> 0 | H14: =IF(E14=1,1,0) -> 0 | I14: =IF(E14=0,1,0) -> 0 | J14: =IF(F14=3,1,0) -> 0 | K14: =IF(F14=1,1,0) -> 0 | L14: =IF(F14=0,1,0) -> 0 | N14: ='Proposte d''Acquisto'!B3 -> ENRICO | O14: =IF(W14>X14,3,IF(W14<X14,0,IF(W14="","",1))) | P14: =IF(X14>W14,3,IF(X14<W14,0,IF(X14="","",1))) | Q14: =IF(O14=3,1,0) -> 0 | R14: =IF(O14=1,1,0) -> 0 | S14: =IF(O14=0,1,0) -> 0 | T14: =IF(P14=3,1,0) -> 0 | U14: =IF(P14=1,1,0) -> 0 | V14: =IF(P14=0,1,0) -> 0 | AB14: ='Proposte d''Acquisto'!B18 -> DANIELE | AC14: =IF(Z14>AA14,3,IF(Z14<AA14,0,IF(Z14="","",1))) | AD14: =IF(AA14>Z14,3,IF(AA14<Z14,0,IF(AA14="","",1))) | AE14: =IF(AC14=3,1,0) -> 0 | AF14: =IF(AC14=1,1,0) -> 0 | AG14: =IF(AC14=0,1,0) -> 0 | AH14: =IF(AD14=3,1,0) -> 0 | AI14: =IF(AD14=1,1,0) -> 0 | AJ14: =IF(AD14=0,1,0) -> 0 | AL14: ='Proposte d''Acquisto'!B3 -> ENRICO | AM14: =IF(AU14>AV14,3,IF(AU14<AV14,0,IF(AU14="","",1))) | AN14: =IF(AV14>AU14,3,IF(AV14<AU14,0,IF(AV14="","",1))) | AO14: =IF(AM14=3,1,0) -> 0 | AP14: =IF(AM14=1,1,0) -> 0 | AQ14: =IF(AM14=0,1,0) -> 0 | AR14: =IF(AN14=3,1,0) -> 0 | AS14: =IF(AN14=1,1,0) -> 0 | AT14: =IF(AN14=0,1,0) -> 0 | AX14: Molina | AY14: =AZ14*3+BA14 -> 0 | BC14: =SUM(AZ14,BA14,BB14) -> 0 | BF14: =SUM(BD14-BE14) -> 0 | BG14: =IF(BH14="*",0,SUM(BB14*Premi!H5+BA14*Premi!H4)) -> 0 | BI14: =SUM($E$7,$O$7,$F$12,$P$12,$E$20,$O$20,$F$25,$P$25,$E$35,$O$35,$E$41,$O$41,$F$49,$P$49,$AC$7,$AM$7,$AD$12,$AN$12,$AC$20,$AM$20,$AD$25,$AN$25,$AC$35,$AM$35,$AC$41,$AM$41,$AD$49,$AN$49) -> 0 | BJ14: 0 | BK14: =(BF14*1000)+BD14 -> 0
AX16: Daniele | AY16: =AZ16*3+BA16 -> 0 | BC16: =SUM(AZ16,BA16,BB16) -> 0 | BF16: =SUM(BD16-BE16) -> 0 | BG16: =IF(BH16="*",0,SUM(BB16*Premi!H5+BA16*Premi!H4)) -> 0 | BI16: =SUM($E$6,$O$6,$AC$6,$AM$6,$F$13,$P$13,$AD$13,$AN$13,$E$18,$O$18,$AC$18,$AM$18,$F$27,$P$27,$AD$27,$AN$27,$E$33,$O$33,$AC$33,$AM$33,$F$41,$P$41,$AD$41,$AN$41,$E$48,$O$48,$AC$48,$AM$48) -> 0 | BJ16: 0 | BK16: =(BF16*1000)+BD16 -> 0
B17: ANDATA | D17: 3ª GIORNATA - 1° GIRONE | W17: RITORNO | Z17: ANDATA | AB17: 3ª GIORNATA - 2° GIRONE | AU17: RITORNO
D18: ='Proposte d''Acquisto'!B23 -> MOLINA | E18: =IF(B18>C18,3,IF(B18<C18,0,IF(B18="","",1))) | F18: =IF(C18>B18,3,IF(C18<B18,0,IF(C18="","",1))) | G18: =IF(E18=3,1,0) -> 0 | H18: =IF(E18=1,1,0) -> 0 | I18: =IF(E18=0,1,0) -> 0 | J18: =IF(F18=3,1,0) -> 0 | K18: =IF(F18=1,1,0) -> 0 | L18: =IF(F18=0,1,0) -> 0 | N18: ='Proposte d''Acquisto'!B13 -> FABRIZIO | O18: =IF(W18>X18,3,IF(W18<X18,0,IF(W18="","",1))) | P18: =IF(X18>W18,3,IF(X18<W18,0,IF(X18="","",1))) | Q18: =IF(O18=3,1,0) -> 0 | R18: =IF(O18=1,1,0) -> 0 | S18: =IF(O18=0,1,0) -> 0 | T18: =IF(P18=3,1,0) -> 0 | U18: =IF(P18=1,1,0) -> 0 | V18: =IF(P18=0,1,0) -> 0 | AB18: ='Proposte d''Acquisto'!B23 -> MOLINA | AC18: =IF(Z18>AA18,3,IF(Z18<AA18,0,IF(Z18="","",1))) | AD18: =IF(AA18>Z18,3,IF(AA18<Z18,0,IF(AA18="","",1))) | AE18: =IF(AC18=3,1,0) -> 0 | AF18: =IF(AC18=1,1,0) -> 0 | AG18: =IF(AC18=0,1,0) -> 0 | AH18: =IF(AD18=3,1,0) -> 0 | AI18: =IF(AD18=1,1,0) -> 0 | AJ18: =IF(AD18=0,1,0) -> 0 | AL18: ='Proposte d''Acquisto'!B13 -> FABRIZIO | AM18: =IF(AU18>AV18,3,IF(AU18<AV18,0,IF(AU18="","",1))) | AN18: =IF(AV18>AU18,3,IF(AV18<AU18,0,IF(AV18="","",1))) | AO18: =IF(AM18=3,1,0) -> 0 | AP18: =IF(AM18=1,1,0) -> 0 | AQ18: =IF(AM18=0,1,0) -> 0 | AR18: =IF(AN18=3,1,0) -> 0 | AS18: =IF(AN18=1,1,0) -> 0 | AT18: =IF(AN18=0,1,0) -> 0 | AX18: Fabrizio | AY18: =AZ18*3+BA18 -> 0 | BC18: =SUM(AZ18,BA18,BB18) -> 0 | BF18: =SUM(BD18-BE18) -> 0 | BG18: =IF(BH18="*",0,SUM(BB18*Premi!H5+BA18*Premi!H4)) -> 0 | BI18: =SUM($F$5,$P$5,$AD$5,$AN$5,$E$13,$O$13,$AC$13,$AM$13,$E$19,$O$19,$AC$19,$AM$19,$F$28,$P$28,$AD$28,$AN$28,$F$42,$P$42,$AD$42,$AN$42,$E$49,$O$49,$AC$49,$AM$49,$AM$34,$AC$34,$E$34,$O$34) -> 0 | BJ18: 0 | BK18: =(BF18*1000)+BD18 -> 0
D19: ='Proposte d''Acquisto'!B38 -> DARIO | E19: =IF(B19>C19,3,IF(B19<C19,0,IF(B19="","",1))) | F19: =IF(C19>B19,3,IF(C19<B19,0,IF(C19="","",1))) | G19: =IF(E19=3,1,0) -> 0 | H19: =IF(E19=1,1,0) -> 0 | I19: =IF(E19=0,1,0) -> 0 | J19: =IF(F19=3,1,0) -> 0 | K19: =IF(F19=1,1,0) -> 0 | L19: =IF(F19=0,1,0) -> 0 | N19: ='Proposte d''Acquisto'!B18 -> DANIELE | O19: =IF(W19>X19,3,IF(W19<X19,0,IF(W19="","",1))) | P19: =IF(X19>W19,3,IF(X19<W19,0,IF(X19="","",1))) | Q19: =IF(O19=3,1,0) -> 0 | R19: =IF(O19=1,1,0) -> 0 | S19: =IF(O19=0,1,0) -> 0 | T19: =IF(P19=3,1,0) -> 0 | U19: =IF(P19=1,1,0) -> 0 | V19: =IF(P19=0,1,0) -> 0 | AB19: ='Proposte d''Acquisto'!B38 -> DARIO | AC19: =IF(Z19>AA19,3,IF(Z19<AA19,0,IF(Z19="","",1))) | AD19: =IF(AA19>Z19,3,IF(AA19<Z19,0,IF(AA19="","",1))) | AE19: =IF(AC19=3,1,0) -> 0 | AF19: =IF(AC19=1,1,0) -> 0 | AG19: =IF(AC19=0,1,0) -> 0 | AH19: =IF(AD19=3,1,0) -> 0 | AI19: =IF(AD19=1,1,0) -> 0 | AJ19: =IF(AD19=0,1,0) -> 0 | AL19: ='Proposte d''Acquisto'!B18 -> DANIELE | AM19: =IF(AU19>AV19,3,IF(AU19<AV19,0,IF(AU19="","",1))) | AN19: =IF(AV19>AU19,3,IF(AV19<AU19,0,IF(AV19="","",1))) | AO19: =IF(AM19=3,1,0) -> 0 | AP19: =IF(AM19=1,1,0) -> 0 | AQ19: =IF(AM19=0,1,0) -> 0 | AR19: =IF(AN19=3,1,0) -> 0 | AS19: =IF(AN19=1,1,0) -> 0 | AT19: =IF(AN19=0,1,0) -> 0
D20: ='Proposte d''Acquisto'!B33 -> VINCENZO | E20: =IF(B20>C20,3,IF(B20<C20,0,IF(B20="","",1))) | F20: =IF(C20>B20,3,IF(C20<B20,0,IF(C20="","",1))) | G20: =IF(E20=3,1,0) -> 0 | H20: =IF(E20=1,1,0) -> 0 | I20: =IF(E20=0,1,0) -> 0 | J20: =IF(F20=3,1,0) -> 0 | K20: =IF(F20=1,1,0) -> 0 | L20: =IF(F20=0,1,0) -> 0 | N20: ='Proposte d''Acquisto'!B8 -> RICCARDO | O20: =IF(W20>X20,3,IF(W20<X20,0,IF(W20="","",1))) | P20: =IF(X20>W20,3,IF(X20<W20,0,IF(X20="","",1))) | Q20: =IF(O20=3,1,0) -> 0 | R20: =IF(O20=1,1,0) -> 0 | S20: =IF(O20=0,1,0) -> 0 | T20: =IF(P20=3,1,0) -> 0 | U20: =IF(P20=1,1,0) -> 0 | V20: =IF(P20=0,1,0) -> 0 | AB20: ='Proposte d''Acquisto'!B33 -> VINCENZO | AC20: =IF(Z20>AA20,3,IF(Z20<AA20,0,IF(Z20="","",1))) | AD20: =IF(AA20>Z20,3,IF(AA20<Z20,0,IF(AA20="","",1))) | AE20: =IF(AC20=3,1,0) -> 0 | AF20: =IF(AC20=1,1,0) -> 0 | AG20: =IF(AC20=0,1,0) -> 0 | AH20: =IF(AD20=3,1,0) -> 0 | AI20: =IF(AD20=1,1,0) -> 0 | AJ20: =IF(AD20=0,1,0) -> 0 | AL20: ='Proposte d''Acquisto'!B8 -> RICCARDO | AM20: =IF(AU20>AV20,3,IF(AU20<AV20,0,IF(AU20="","",1))) | AN20: =IF(AV20>AU20,3,IF(AV20<AU20,0,IF(AV20="","",1))) | AO20: =IF(AM20=3,1,0) -> 0 | AP20: =IF(AM20=1,1,0) -> 0 | AQ20: =IF(AM20=0,1,0) -> 0 | AR20: =IF(AN20=3,1,0) -> 0 | AS20: =IF(AN20=1,1,0) -> 0 | AT20: =IF(AN20=0,1,0) -> 0 | AX20: Dario | AY20: =AZ20*3+BA20 -> 0 | BC20: =SUM(AZ20,BA20,BB20) -> 0 | BF20: =SUM(BD20-BE20) -> 0 | BG20: =IF(BH20="*",0,SUM(BB20*Premi!H5+BA20*Premi!H4)) -> 0 | BI20: =SUM($E$4,$O$4,$AC$4,$AM$4,$F$14,$P$14,$AD$14,$AN$14,$F$21,$P$21,$AD$21,$AN$21,$E$25,$O$25,$AC$25,$AM$25,$F$34,$P$34,$AD$34,$AN$34,$E$40,$O$40,$AC$40,$AM$40,$F$48,$P$48,$AD$48,$AN$48) -> 0 | BJ20: 0 | BK20: =(BF20*1000)+BD20 -> 0
D21: ='Proposte d''Acquisto'!B28 -> EUGENIO | E21: =IF(B21>C21,3,IF(B21<C21,0,IF(B21="","",1))) | F21: =IF(C21>B21,3,IF(C21<B21,0,IF(C21="","",1))) | G21: =IF(E21=3,1,0) -> 0 | H21: =IF(E21=1,1,0) -> 0 | I21: =IF(E21=0,1,0) -> 0 | J21: =IF(F21=3,1,0) -> 0 | K21: =IF(F21=1,1,0) -> 0 | L21: =IF(F21=0,1,0) -> 0 | N21: ='Proposte d''Acquisto'!B3 -> ENRICO | O21: =IF(W21>X21,3,IF(W21<X21,0,IF(W21="","",1))) | P21: =IF(X21>W21,3,IF(X21<W21,0,IF(X21="","",1))) | Q21: =IF(O21=3,1,0) -> 0 | R21: =IF(O21=1,1,0) -> 0 | S21: =IF(O21=0,1,0) -> 0 | T21: =IF(P21=3,1,0) -> 0 | U21: =IF(P21=1,1,0) -> 0 | V21: =IF(P21=0,1,0) -> 0 | AB21: ='Proposte d''Acquisto'!B28 -> EUGENIO | AC21: =IF(Z21>AA21,3,IF(Z21<AA21,0,IF(Z21="","",1))) | AD21: =IF(AA21>Z21,3,IF(AA21<Z21,0,IF(AA21="","",1))) | AE21: =IF(AC21=3,1,0) -> 0 | AF21: =IF(AC21=1,1,0) -> 0 | AG21: =IF(AC21=0,1,0) -> 0 | AH21: =IF(AD21=3,1,0) -> 0 | AI21: =IF(AD21=1,1,0) -> 0 | AJ21: =IF(AD21=0,1,0) -> 0 | AL21: ='Proposte d''Acquisto'!B3 -> ENRICO | AM21: =IF(AU21>AV21,3,IF(AU21<AV21,0,IF(AU21="","",1))) | AN21: =IF(AV21>AU21,3,IF(AV21<AU21,0,IF(AV21="","",1))) | AO21: =IF(AM21=3,1,0) -> 0 | AP21: =IF(AM21=1,1,0) -> 0 | AQ21: =IF(AM21=0,1,0) -> 0 | AR21: =IF(AN21=3,1,0) -> 0 | AS21: =IF(AN21=1,1,0) -> 0 | AT21: =IF(AN21=0,1,0) -> 0
B24: ANDATA | D24: 4ª GIORNATA - 1° GIRONE | W24: RITORNO | Z24: ANDATA | AB24: 4ª GIORNATA - 2° GIRONE | AU24: RITORNO
D25: ='Proposte d''Acquisto'!B3 -> ENRICO | E25: =IF(B25>C25,3,IF(B25<C25,0,IF(B25="","",1))) | F25: =IF(C25>B25,3,IF(C25<B25,0,IF(C25="","",1))) | G25: =IF(E25=3,1,0) -> 0 | H25: =IF(E25=1,1,0) -> 0 | I25: =IF(E25=0,1,0) -> 0 | J25: =IF(F25=3,1,0) -> 0 | K25: =IF(F25=1,1,0) -> 0 | L25: =IF(F25=0,1,0) -> 0 | N25: ='Proposte d''Acquisto'!B33 -> VINCENZO | O25: =IF(W25>X25,3,IF(W25<X25,0,IF(W25="","",1))) | P25: =IF(X25>W25,3,IF(X25<W25,0,IF(X25="","",1))) | Q25: =IF(O25=3,1,0) -> 0 | R25: =IF(O25=1,1,0) -> 0 | S25: =IF(O25=0,1,0) -> 0 | T25: =IF(P25=3,1,0) -> 0 | U25: =IF(P25=1,1,0) -> 0 | V25: =IF(P25=0,1,0) -> 0 | AB25: ='Proposte d''Acquisto'!B3 -> ENRICO | AC25: =IF(Z25>AA25,3,IF(Z25<AA25,0,IF(Z25="","",1))) | AD25: =IF(AA25>Z25,3,IF(AA25<Z25,0,IF(AA25="","",1))) | AE25: =IF(AC25=3,1,0) -> 0 | AF25: =IF(AC25=1,1,0) -> 0 | AG25: =IF(AC25=0,1,0) -> 0 | AH25: =IF(AD25=3,1,0) -> 0 | AI25: =IF(AD25=1,1,0) -> 0 | AJ25: =IF(AD25=0,1,0) -> 0 | AL25: ='Proposte d''Acquisto'!B33 -> VINCENZO | AM25: =IF(AU25>AV25,3,IF(AU25<AV25,0,IF(AU25="","",1))) | AN25: =IF(AV25>AU25,3,IF(AV25<AU25,0,IF(AV25="","",1))) | AO25: =IF(AM25=3,1,0) -> 0 | AP25: =IF(AM25=1,1,0) -> 0 | AQ25: =IF(AM25=0,1,0) -> 0 | AR25: =IF(AN25=3,1,0) -> 0 | AS25: =IF(AN25=1,1,0) -> 0 | AT25: =IF(AN25=0,1,0) -> 0
D26: ='Proposte d''Acquisto'!B28 -> EUGENIO | E26: =IF(B26>C26,3,IF(B26<C26,0,IF(B26="","",1))) | F26: =IF(C26>B26,3,IF(C26<B26,0,IF(C26="","",1))) | G26: =IF(E26=3,1,0) -> 0 | H26: =IF(E26=1,1,0) -> 0 | I26: =IF(E26=0,1,0) -> 0 | J26: =IF(F26=3,1,0) -> 0 | K26: =IF(F26=1,1,0) -> 0 | L26: =IF(F26=0,1,0) -> 0 | N26: ='Proposte d''Acquisto'!B13 -> FABRIZIO | O26: =IF(W26>X26,3,IF(W26<X26,0,IF(W26="","",1))) | P26: =IF(X26>W26,3,IF(X26<W26,0,IF(X26="","",1))) | Q26: =IF(O26=3,1,0) -> 0 | R26: =IF(O26=1,1,0) -> 0 | S26: =IF(O26=0,1,0) -> 0 | T26: =IF(P26=3,1,0) -> 0 | U26: =IF(P26=1,1,0) -> 0 | V26: =IF(P26=0,1,0) -> 0 | AB26: ='Proposte d''Acquisto'!B28 -> EUGENIO | AC26: =IF(Z26>AA26,3,IF(Z26<AA26,0,IF(Z26="","",1))) | AD26: =IF(AA26>Z26,3,IF(AA26<Z26,0,IF(AA26="","",1))) | AE26: =IF(AC26=3,1,0) -> 0 | AF26: =IF(AC26=1,1,0) -> 0 | AG26: =IF(AC26=0,1,0) -> 0 | AH26: =IF(AD26=3,1,0) -> 0 | AI26: =IF(AD26=1,1,0) -> 0 | AJ26: =IF(AD26=0,1,0) -> 0 | AL26: ='Proposte d''Acquisto'!B13 -> FABRIZIO | AM26: =IF(AU26>AV26,3,IF(AU26<AV26,0,IF(AU26="","",1))) | AN26: =IF(AV26>AU26,3,IF(AV26<AU26,0,IF(AV26="","",1))) | AO26: =IF(AM26=3,1,0) -> 0 | AP26: =IF(AM26=1,1,0) -> 0 | AQ26: =IF(AM26=0,1,0) -> 0 | AR26: =IF(AN26=3,1,0) -> 0 | AS26: =IF(AN26=1,1,0) -> 0 | AT26: =IF(AN26=0,1,0) -> 0
D27: ='Proposte d''Acquisto'!B18 -> DANIELE | E27: =IF(B27>C27,3,IF(B27<C27,0,IF(B27="","",1))) | F27: =IF(C27>B27,3,IF(C27<B27,0,IF(C27="","",1))) | G27: =IF(E27=3,1,0) -> 0 | H27: =IF(E27=1,1,0) -> 0 | I27: =IF(E27=0,1,0) -> 0 | J27: =IF(F27=3,1,0) -> 0 | K27: =IF(F27=1,1,0) -> 0 | L27: =IF(F27=0,1,0) -> 0 | N27: ='Proposte d''Acquisto'!B23 -> MOLINA | O27: =IF(W27>X27,3,IF(W27<X27,0,IF(W27="","",1))) | P27: =IF(X27>W27,3,IF(X27<W27,0,IF(X27="","",1))) | Q27: =IF(O27=3,1,0) -> 0 | R27: =IF(O27=1,1,0) -> 0 | S27: =IF(O27=0,1,0) -> 0 | T27: =IF(P27=3,1,0) -> 0 | U27: =IF(P27=1,1,0) -> 0 | V27: =IF(P27=0,1,0) -> 0 | AB27: ='Proposte d''Acquisto'!B18 -> DANIELE | AC27: =IF(Z27>AA27,3,IF(Z27<AA27,0,IF(Z27="","",1))) | AD27: =IF(AA27>Z27,3,IF(AA27<Z27,0,IF(AA27="","",1))) | AE27: =IF(AC27=3,1,0) -> 0 | AF27: =IF(AC27=1,1,0) -> 0 | AG27: =IF(AC27=0,1,0) -> 0 | AH27: =IF(AD27=3,1,0) -> 0 | AI27: =IF(AD27=1,1,0) -> 0 | AJ27: =IF(AD27=0,1,0) -> 0 | AL27: ='Proposte d''Acquisto'!B23 -> MOLINA | AM27: =IF(AU27>AV27,3,IF(AU27<AV27,0,IF(AU27="","",1))) | AN27: =IF(AV27>AU27,3,IF(AV27<AU27,0,IF(AV27="","",1))) | AO27: =IF(AM27=3,1,0) -> 0 | AP27: =IF(AM27=1,1,0) -> 0 | AQ27: =IF(AM27=0,1,0) -> 0 | AR27: =IF(AN27=3,1,0) -> 0 | AS27: =IF(AN27=1,1,0) -> 0 | AT27: =IF(AN27=0,1,0) -> 0
D28: ='Proposte d''Acquisto'!B8 -> RICCARDO | E28: =IF(B28>C28,3,IF(B28<C28,0,IF(B28="","",1))) | F28: =IF(C28>B28,3,IF(C28<B28,0,IF(C28="","",1))) | G28: =IF(E28=3,1,0) -> 0 | H28: =IF(E28=1,1,0) -> 0 | I28: =IF(E28=0,1,0) -> 0 | J28: =IF(F28=3,1,0) -> 0 | K28: =IF(F28=1,1,0) -> 0 | L28: =IF(F28=0,1,0) -> 0 | N28: ='Proposte d''Acquisto'!B38 -> DARIO | O28: =IF(W28>X28,3,IF(W28<X28,0,IF(W28="","",1))) | P28: =IF(X28>W28,3,IF(X28<W28,0,IF(X28="","",1))) | Q28: =IF(O28=3,1,0) -> 0 | R28: =IF(O28=1,1,0) -> 0 | S28: =IF(O28=0,1,0) -> 0 | T28: =IF(P28=3,1,0) -> 0 | U28: =IF(P28=1,1,0) -> 0 | V28: =IF(P28=0,1,0) -> 0 | AB28: ='Proposte d''Acquisto'!B8 -> RICCARDO | AC28: =IF(Z28>AA28,3,IF(Z28<AA28,0,IF(Z28="","",1))) | AD28: =IF(AA28>Z28,3,IF(AA28<Z28,0,IF(AA28="","",1))) | AE28: =IF(AC28=3,1,0) -> 0 | AF28: =IF(AC28=1,1,0) -> 0 | AG28: =IF(AC28=0,1,0) -> 0 | AH28: =IF(AD28=3,1,0) -> 0 | AI28: =IF(AD28=1,1,0) -> 0 | AJ28: =IF(AD28=0,1,0) -> 0 | AL28: ='Proposte d''Acquisto'!B38 -> DARIO | AM28: =IF(AU28>AV28,3,IF(AU28<AV28,0,IF(AU28="","",1))) | AN28: =IF(AV28>AU28,3,IF(AV28<AU28,0,IF(AV28="","",1))) | AO28: =IF(AM28=3,1,0) -> 0 | AP28: =IF(AM28=1,1,0) -> 0 | AQ28: =IF(AM28=0,1,0) -> 0 | AR28: =IF(AN28=3,1,0) -> 0 | AS28: =IF(AN28=1,1,0) -> 0 | AT28: =IF(AN28=0,1,0) -> 0
B31: ANDATA | D31: 5ª GIORNATA - 1° GIRONE | W31: RITORNO | Z31: ANDATA | AB31: 5ª GIORNATA - 2° GIRONE | AU31: RITORNO
D32: ='Proposte d''Acquisto'!B13 -> FABRIZIO | E32: =IF(B32>C32,3,IF(B32<C32,0,IF(B32="","",1))) | F32: =IF(C32>B32,3,IF(C32<B32,0,IF(C32="","",1))) | G32: =IF(E32=3,1,0) -> 0 | H32: =IF(E32=1,1,0) -> 0 | I32: =IF(E32=0,1,0) -> 0 | J32: =IF(F32=3,1,0) -> 0 | K32: =IF(F32=1,1,0) -> 0 | L32: =IF(F32=0,1,0) -> 0 | N32: ='Proposte d''Acquisto'!B18 -> DANIELE | O32: =IF(W32>X32,3,IF(W32<X32,0,IF(W32="","",1))) | P32: =IF(X32>W32,3,IF(X32<W32,0,IF(X32="","",1))) | Q32: =IF(O32=3,1,0) -> 0 | R32: =IF(O32=1,1,0) -> 0 | S32: =IF(O32=0,1,0) -> 0 | T32: =IF(P32=3,1,0) -> 0 | U32: =IF(P32=1,1,0) -> 0 | V32: =IF(P32=0,1,0) -> 0 | AB32: ='Proposte d''Acquisto'!B13 -> FABRIZIO | AC32: =IF(Z32>AA32,3,IF(Z32<AA32,0,IF(Z32="","",1))) | AD32: =IF(AA32>Z32,3,IF(AA32<Z32,0,IF(AA32="","",1))) | AE32: =IF(AC32=3,1,0) -> 0 | AF32: =IF(AC32=1,1,0) -> 0 | AG32: =IF(AC32=0,1,0) -> 0 | AH32: =IF(AD32=3,1,0) -> 0 | AI32: =IF(AD32=1,1,0) -> 0 | AJ32: =IF(AD32=0,1,0) -> 0 | AL32: ='Proposte d''Acquisto'!B18 -> DANIELE | AM32: =IF(AU32>AV32,3,IF(AU32<AV32,0,IF(AU32="","",1))) | AN32: =IF(AV32>AU32,3,IF(AV32<AU32,0,IF(AV32="","",1))) | AO32: =IF(AM32=3,1,0) -> 0 | AP32: =IF(AM32=1,1,0) -> 0 | AQ32: =IF(AM32=0,1,0) -> 0 | AR32: =IF(AN32=3,1,0) -> 0 | AS32: =IF(AN32=1,1,0) -> 0 | AT32: =IF(AN32=0,1,0) -> 0
D33: ='Proposte d''Acquisto'!B23 -> MOLINA | E33: =IF(B33>C33,3,IF(B33<C33,0,IF(B33="","",1))) | F33: =IF(C33>B33,3,IF(C33<B33,0,IF(C33="","",1))) | G33: =IF(E33=3,1,0) -> 0 | H33: =IF(E33=1,1,0) -> 0 | I33: =IF(E33=0,1,0) -> 0 | J33: =IF(F33=3,1,0) -> 0 | K33: =IF(F33=1,1,0) -> 0 | L33: =IF(F33=0,1,0) -> 0 | N33: ='Proposte d''Acquisto'!B8 -> RICCARDO | O33: =IF(W33>X33,3,IF(W33<X33,0,IF(W33="","",1))) | P33: =IF(X33>W33,3,IF(X33<W33,0,IF(X33="","",1))) | Q33: =IF(O33=3,1,0) -> 0 | R33: =IF(O33=1,1,0) -> 0 | S33: =IF(O33=0,1,0) -> 0 | T33: =IF(P33=3,1,0) -> 0 | U33: =IF(P33=1,1,0) -> 0 | V33: =IF(P33=0,1,0) -> 0 | AB33: ='Proposte d''Acquisto'!B23 -> MOLINA | AC33: =IF(Z33>AA33,3,IF(Z33<AA33,0,IF(Z33="","",1))) | AD33: =IF(AA33>Z33,3,IF(AA33<Z33,0,IF(AA33="","",1))) | AE33: =IF(AC33=3,1,0) -> 0 | AF33: =IF(AC33=1,1,0) -> 0 | AG33: =IF(AC33=0,1,0) -> 0 | AH33: =IF(AD33=3,1,0) -> 0 | AI33: =IF(AD33=1,1,0) -> 0 | AJ33: =IF(AD33=0,1,0) -> 0 | AL33: ='Proposte d''Acquisto'!B8 -> RICCARDO | AM33: =IF(AU33>AV33,3,IF(AU33<AV33,0,IF(AU33="","",1))) | AN33: =IF(AV33>AU33,3,IF(AV33<AU33,0,IF(AV33="","",1))) | AO33: =IF(AM33=3,1,0) -> 0 | AP33: =IF(AM33=1,1,0) -> 0 | AQ33: =IF(AM33=0,1,0) -> 0 | AR33: =IF(AN33=3,1,0) -> 0 | AS33: =IF(AN33=1,1,0) -> 0 | AT33: =IF(AN33=0,1,0) -> 0
D34: ='Proposte d''Acquisto'!B38 -> DARIO | E34: =IF(B34>C34,3,IF(B34<C34,0,IF(B34="","",1))) | F34: =IF(C34>B34,3,IF(C34<B34,0,IF(C34="","",1))) | G34: =IF(E34=3,1,0) -> 0 | H34: =IF(E34=1,1,0) -> 0 | I34: =IF(E34=0,1,0) -> 0 | J34: =IF(F34=3,1,0) -> 0 | K34: =IF(F34=1,1,0) -> 0 | L34: =IF(F34=0,1,0) -> 0 | N34: ='Proposte d''Acquisto'!B3 -> ENRICO | O34: =IF(W34>X34,3,IF(W34<X34,0,IF(W34="","",1))) | P34: =IF(X34>W34,3,IF(X34<W34,0,IF(X34="","",1))) | Q34: =IF(O34=3,1,0) -> 0 | R34: =IF(O34=1,1,0) -> 0 | S34: =IF(O34=0,1,0) -> 0 | T34: =IF(P34=3,1,0) -> 0 | U34: =IF(P34=1,1,0) -> 0 | V34: =IF(P34=0,1,0) -> 0 | AB34: ='Proposte d''Acquisto'!B38 -> DARIO | AC34: =IF(Z34>AA34,3,IF(Z34<AA34,0,IF(Z34="","",1))) | AD34: =IF(AA34>Z34,3,IF(AA34<Z34,0,IF(AA34="","",1))) | AE34: =IF(AC34=3,1,0) -> 0 | AF34: =IF(AC34=1,1,0) -> 0 | AG34: =IF(AC34=0,1,0) -> 0 | AH34: =IF(AD34=3,1,0) -> 0 | AI34: =IF(AD34=1,1,0) -> 0 | AJ34: =IF(AD34=0,1,0) -> 0 | AL34: ='Proposte d''Acquisto'!B3 -> ENRICO | AM34: =IF(AU34>AV34,3,IF(AU34<AV34,0,IF(AU34="","",1))) | AN34: =IF(AV34>AU34,3,IF(AV34<AU34,0,IF(AV34="","",1))) | AO34: =IF(AM34=3,1,0) -> 0 | AP34: =IF(AM34=1,1,0) -> 0 | AQ34: =IF(AM34=0,1,0) -> 0 | AR34: =IF(AN34=3,1,0) -> 0 | AS34: =IF(AN34=1,1,0) -> 0 | AT34: =IF(AN34=0,1,0) -> 0
D35: ='Proposte d''Acquisto'!B33 -> VINCENZO | E35: =IF(B35>C35,3,IF(B35<C35,0,IF(B35="","",1))) | F35: =IF(C35>B35,3,IF(C35<B35,0,IF(C35="","",1))) | G35: =IF(E35=3,1,0) -> 0 | H35: =IF(E35=1,1,0) -> 0 | I35: =IF(E35=0,1,0) -> 0 | J35: =IF(F35=3,1,0) -> 0 | K35: =IF(F35=1,1,0) -> 0 | L35: =IF(F35=0,1,0) -> 0 | N35: ='Proposte d''Acquisto'!B28 -> EUGENIO | O35: =IF(W35>X35,3,IF(W35<X35,0,IF(W35="","",1))) | P35: =IF(X35>W35,3,IF(X35<W35,0,IF(X35="","",1))) | Q35: =IF(O35=3,1,0) -> 0 | R35: =IF(O35=1,1,0) -> 0 | S35: =IF(O35=0,1,0) -> 0 | T35: =IF(P35=3,1,0) -> 0 | U35: =IF(P35=1,1,0) -> 0 | V35: =IF(P35=0,1,0) -> 0 | AB35: ='Proposte d''Acquisto'!B33 -> VINCENZO | AC35: =IF(Z35>AA35,3,IF(Z35<AA35,0,IF(Z35="","",1))) | AD35: =IF(AA35>Z35,3,IF(AA35<Z35,0,IF(AA35="","",1))) | AE35: =IF(AC35=3,1,0) -> 0 | AF35: =IF(AC35=1,1,0) -> 0 | AG35: =IF(AC35=0,1,0) -> 0 | AH35: =IF(AD35=3,1,0) -> 0 | AI35: =IF(AD35=1,1,0) -> 0 | AJ35: =IF(AD35=0,1,0) -> 0 | AL35: ='Proposte d''Acquisto'!B28 -> EUGENIO | AM35: =IF(AU35>AV35,3,IF(AU35<AV35,0,IF(AU35="","",1))) | AN35: =IF(AV35>AU35,3,IF(AV35<AU35,0,IF(AV35="","",1))) | AO35: =IF(AM35=3,1,0) -> 0 | AP35: =IF(AM35=1,1,0) -> 0 | AQ35: =IF(AM35=0,1,0) -> 0 | AR35: =IF(AN35=3,1,0) -> 0 | AS35: =IF(AN35=1,1,0) -> 0 | AT35: =IF(AN35=0,1,0) -> 0
B38: ANDATA | D38: 6ª GIORNATA - 1° GIRONE | W38: RITORNO | Z38: ANDATA | AB38: 6ª GIORNATA - 2° GIRONE | AU38: RITORNO
D39: ='Proposte d''Acquisto'!B8 -> RICCARDO | E39: =IF(B39>C39,3,IF(B39<C39,0,IF(B39="","",1))) | F39: =IF(C39>B39,3,IF(C39<B39,0,IF(C39="","",1))) | G39: =IF(E39=3,1,0) -> 0 | H39: =IF(E39=1,1,0) -> 0 | I39: =IF(E39=0,1,0) -> 0 | J39: =IF(F39=3,1,0) -> 0 | K39: =IF(F39=1,1,0) -> 0 | L39: =IF(F39=0,1,0) -> 0 | N39: ='Proposte d''Acquisto'!B18 -> DANIELE | O39: =IF(W39>X39,3,IF(W39<X39,0,IF(W39="","",1))) | P39: =IF(X39>W39,3,IF(X39<W39,0,IF(X39="","",1))) | Q39: =IF(O39=3,1,0) -> 0 | R39: =IF(O39=1,1,0) -> 0 | S39: =IF(O39=0,1,0) -> 0 | T39: =IF(P39=3,1,0) -> 0 | U39: =IF(P39=1,1,0) -> 0 | V39: =IF(P39=0,1,0) -> 0 | AB39: ='Proposte d''Acquisto'!B8 -> RICCARDO | AC39: =IF(Z39>AA39,3,IF(Z39<AA39,0,IF(Z39="","",1))) | AD39: =IF(AA39>Z39,3,IF(AA39<Z39,0,IF(AA39="","",1))) | AE39: =IF(AC39=3,1,0) -> 0 | AF39: =IF(AC39=1,1,0) -> 0 | AG39: =IF(AC39=0,1,0) -> 0 | AH39: =IF(AD39=3,1,0) -> 0 | AI39: =IF(AD39=1,1,0) -> 0 | AJ39: =IF(AD39=0,1,0) -> 0 | AL39: ='Proposte d''Acquisto'!B18 -> DANIELE | AM39: =IF(AU39>AV39,3,IF(AU39<AV39,0,IF(AU39="","",1))) | AN39: =IF(AV39>AU39,3,IF(AV39<AU39,0,IF(AV39="","",1))) | AO39: =IF(AM39=3,1,0) -> 0 | AP39: =IF(AM39=1,1,0) -> 0 | AQ39: =IF(AM39=0,1,0) -> 0 | AR39: =IF(AN39=3,1,0) -> 0 | AS39: =IF(AN39=1,1,0) -> 0 | AT39: =IF(AN39=0,1,0) -> 0
D40: ='Proposte d''Acquisto'!B3 -> ENRICO | E40: =IF(B40>C40,3,IF(B40<C40,0,IF(B40="","",1))) | F40: =IF(C40>B40,3,IF(C40<B40,0,IF(C40="","",1))) | G40: =IF(E40=3,1,0) -> 0 | H40: =IF(E40=1,1,0) -> 0 | I40: =IF(E40=0,1,0) -> 0 | J40: =IF(F40=3,1,0) -> 0 | K40: =IF(F40=1,1,0) -> 0 | L40: =IF(F40=0,1,0) -> 0 | N40: ='Proposte d''Acquisto'!B13 -> FABRIZIO | O40: =IF(W40>X40,3,IF(W40<X40,0,IF(W40="","",1))) | P40: =IF(X40>W40,3,IF(X40<W40,0,IF(X40="","",1))) | Q40: =IF(O40=3,1,0) -> 0 | R40: =IF(O40=1,1,0) -> 0 | S40: =IF(O40=0,1,0) -> 0 | T40: =IF(P40=3,1,0) -> 0 | U40: =IF(P40=1,1,0) -> 0 | V40: =IF(P40=0,1,0) -> 0 | AB40: ='Proposte d''Acquisto'!B3 -> ENRICO | AC40: =IF(Z40>AA40,3,IF(Z40<AA40,0,IF(Z40="","",1))) | AD40: =IF(AA40>Z40,3,IF(AA40<Z40,0,IF(AA40="","",1))) | AE40: =IF(AC40=3,1,0) -> 0 | AF40: =IF(AC40=1,1,0) -> 0 | AG40: =IF(AC40=0,1,0) -> 0 | AH40: =IF(AD40=3,1,0) -> 0 | AI40: =IF(AD40=1,1,0) -> 0 | AJ40: =IF(AD40=0,1,0) -> 0 | AL40: ='Proposte d''Acquisto'!B13 -> FABRIZIO | AM40: =IF(AU40>AV40,3,IF(AU40<AV40,0,IF(AU40="","",1))) | AN40: =IF(AV40>AU40,3,IF(AV40<AU40,0,IF(AV40="","",1))) | AO40: =IF(AM40=3,1,0) -> 0 | AP40: =IF(AM40=1,1,0) -> 0 | AQ40: =IF(AM40=0,1,0) -> 0 | AR40: =IF(AN40=3,1,0) -> 0 | AS40: =IF(AN40=1,1,0) -> 0 | AT40: =IF(AN40=0,1,0) -> 0
D41: ='Proposte d''Acquisto'!B33 -> VINCENZO | E41: =IF(B41>C41,3,IF(B41<C41,0,IF(B41="","",1))) | F41: =IF(C41>B41,3,IF(C41<B41,0,IF(C41="","",1))) | G41: =IF(E41=3,1,0) -> 0 | H41: =IF(E41=1,1,0) -> 0 | I41: =IF(E41=0,1,0) -> 0 | J41: =IF(F41=3,1,0) -> 0 | K41: =IF(F41=1,1,0) -> 0 | L41: =IF(F41=0,1,0) -> 0 | N41: ='Proposte d''Acquisto'!B23 -> MOLINA | O41: =IF(W41>X41,3,IF(W41<X41,0,IF(W41="","",1))) | P41: =IF(X41>W41,3,IF(X41<W41,0,IF(X41="","",1))) | Q41: =IF(O41=3,1,0) -> 0 | R41: =IF(O41=1,1,0) -> 0 | S41: =IF(O41=0,1,0) -> 0 | T41: =IF(P41=3,1,0) -> 0 | U41: =IF(P41=1,1,0) -> 0 | V41: =IF(P41=0,1,0) -> 0 | AB41: ='Proposte d''Acquisto'!B33 -> VINCENZO | AC41: =IF(Z41>AA41,3,IF(Z41<AA41,0,IF(Z41="","",1))) | AD41: =IF(AA41>Z41,3,IF(AA41<Z41,0,IF(AA41="","",1))) | AE41: =IF(AC41=3,1,0) -> 0 | AF41: =IF(AC41=1,1,0) -> 0 | AG41: =IF(AC41=0,1,0) -> 0 | AH41: =IF(AD41=3,1,0) -> 0 | AI41: =IF(AD41=1,1,0) -> 0 | AJ41: =IF(AD41=0,1,0) -> 0 | AL41: ='Proposte d''Acquisto'!B23 -> MOLINA | AM41: =IF(AU41>AV41,3,IF(AU41<AV41,0,IF(AU41="","",1))) | AN41: =IF(AV41>AU41,3,IF(AV41<AU41,0,IF(AV41="","",1))) | AO41: =IF(AM41=3,1,0) -> 0 | AP41: =IF(AM41=1,1,0) -> 0 | AQ41: =IF(AM41=0,1,0) -> 0 | AR41: =IF(AN41=3,1,0) -> 0 | AS41: =IF(AN41=1,1,0) -> 0 | AT41: =IF(AN41=0,1,0) -> 0
D42: ='Proposte d''Acquisto'!B28 -> EUGENIO | E42: =IF(B42>C42,3,IF(B42<C42,0,IF(B42="","",1))) | F42: =IF(C42>B42,3,IF(C42<B42,0,IF(C42="","",1))) | G42: =IF(E42=3,1,0) -> 0 | H42: =IF(E42=1,1,0) -> 0 | I42: =IF(E42=0,1,0) -> 0 | J42: =IF(F42=3,1,0) -> 0 | K42: =IF(F42=1,1,0) -> 0 | L42: =IF(F42=0,1,0) -> 0 | N42: ='Proposte d''Acquisto'!B38 -> DARIO | O42: =IF(W42>X42,3,IF(W42<X42,0,IF(W42="","",1))) | P42: =IF(X42>W42,3,IF(X42<W42,0,IF(X42="","",1))) | Q42: =IF(O42=3,1,0) -> 0 | R42: =IF(O42=1,1,0) -> 0 | S42: =IF(O42=0,1,0) -> 0 | T42: =IF(P42=3,1,0) -> 0 | U42: =IF(P42=1,1,0) -> 0 | V42: =IF(P42=0,1,0) -> 0 | AB42: ='Proposte d''Acquisto'!B28 -> EUGENIO | AC42: =IF(Z42>AA42,3,IF(Z42<AA42,0,IF(Z42="","",1))) | AD42: =IF(AA42>Z42,3,IF(AA42<Z42,0,IF(AA42="","",1))) | AE42: =IF(AC42=3,1,0) -> 0 | AF42: =IF(AC42=1,1,0) -> 0 | AG42: =IF(AC42=0,1,0) -> 0 | AH42: =IF(AD42=3,1,0) -> 0 | AI42: =IF(AD42=1,1,0) -> 0 | AJ42: =IF(AD42=0,1,0) -> 0 | AL42: ='Proposte d''Acquisto'!B38 -> DARIO | AM42: =IF(AU42>AV42,3,IF(AU42<AV42,0,IF(AU42="","",1))) | AN42: =IF(AV42>AU42,3,IF(AV42<AU42,0,IF(AV42="","",1))) | AO42: =IF(AM42=3,1,0) -> 0 | AP42: =IF(AM42=1,1,0) -> 0 | AQ42: =IF(AM42=0,1,0) -> 0 | AR42: =IF(AN42=3,1,0) -> 0 | AS42: =IF(AN42=1,1,0) -> 0 | AT42: =IF(AN42=0,1,0) -> 0
B45: ANDATA | D45: 7ª GIORNATA - 1° GIRONE | W45: RITORNO | Z45: ANDATA | AB45: 7ª GIORNATA - 2° GIRONE | AU45: RITORNO
D46: ='Proposte d''Acquisto'!B18 -> DANIELE | E46: =IF(B46>C46,3,IF(B46<C46,0,IF(B46="","",1))) | F46: =IF(C46>B46,3,IF(C46<B46,0,IF(C46="","",1))) | G46: =IF(E46=3,1,0) -> 0 | H46: =IF(E46=1,1,0) -> 0 | I46: =IF(E46=0,1,0) -> 0 | J46: =IF(F46=3,1,0) -> 0 | K46: =IF(F46=1,1,0) -> 0 | L46: =IF(F46=0,1,0) -> 0 | N46: ='Proposte d''Acquisto'!B28 -> EUGENIO | O46: =IF(W46>X46,3,IF(W46<X46,0,IF(W46="","",1))) | P46: =IF(X46>W46,3,IF(X46<W46,0,IF(X46="","",1))) | Q46: =IF(O46=3,1,0) -> 0 | R46: =IF(O46=1,1,0) -> 0 | S46: =IF(O46=0,1,0) -> 0 | T46: =IF(P46=3,1,0) -> 0 | U46: =IF(P46=1,1,0) -> 0 | V46: =IF(P46=0,1,0) -> 0 | AB46: ='Proposte d''Acquisto'!B18 -> DANIELE | AC46: =IF(Z46>AA46,3,IF(Z46<AA46,0,IF(Z46="","",1))) | AD46: =IF(AA46>Z46,3,IF(AA46<Z46,0,IF(AA46="","",1))) | AE46: =IF(AC46=3,1,0) -> 0 | AF46: =IF(AC46=1,1,0) -> 0 | AG46: =IF(AC46=0,1,0) -> 0 | AH46: =IF(AD46=3,1,0) -> 0 | AI46: =IF(AD46=1,1,0) -> 0 | AJ46: =IF(AD46=0,1,0) -> 0 | AL46: ='Proposte d''Acquisto'!B28 -> EUGENIO | AM46: =IF(AU46>AV46,3,IF(AU46<AV46,0,IF(AU46="","",1))) | AN46: =IF(AV46>AU46,3,IF(AV46<AU46,0,IF(AV46="","",1))) | AO46: =IF(AM46=3,1,0) -> 0 | AP46: =IF(AM46=1,1,0) -> 0 | AQ46: =IF(AM46=0,1,0) -> 0 | AR46: =IF(AN46=3,1,0) -> 0 | AS46: =IF(AN46=1,1,0) -> 0 | AT46: =IF(AN46=0,1,0) -> 0
D47: ='Proposte d''Acquisto'!B13 -> FABRIZIO | E47: =IF(B47>C47,3,IF(B47<C47,0,IF(B47="","",1))) | F47: =IF(C47>B47,3,IF(C47<B47,0,IF(C47="","",1))) | G47: =IF(E47=3,1,0) -> 0 | H47: =IF(E47=1,1,0) -> 0 | I47: =IF(E47=0,1,0) -> 0 | J47: =IF(F47=3,1,0) -> 0 | K47: =IF(F47=1,1,0) -> 0 | L47: =IF(F47=0,1,0) -> 0 | N47: ='Proposte d''Acquisto'!B8 -> RICCARDO | O47: =IF(W47>X47,3,IF(W47<X47,0,IF(W47="","",1))) | P47: =IF(X47>W47,3,IF(X47<W47,0,IF(X47="","",1))) | Q47: =IF(O47=3,1,0) -> 0 | R47: =IF(O47=1,1,0) -> 0 | S47: =IF(O47=0,1,0) -> 0 | T47: =IF(P47=3,1,0) -> 0 | U47: =IF(P47=1,1,0) -> 0 | V47: =IF(P47=0,1,0) -> 0 | AB47: ='Proposte d''Acquisto'!B13 -> FABRIZIO | AC47: =IF(Z47>AA47,3,IF(Z47<AA47,0,IF(Z47="","",1))) | AD47: =IF(AA47>Z47,3,IF(AA47<Z47,0,IF(AA47="","",1))) | AE47: =IF(AC47=3,1,0) -> 0 | AF47: =IF(AC47=1,1,0) -> 0 | AG47: =IF(AC47=0,1,0) -> 0 | AH47: =IF(AD47=3,1,0) -> 0 | AI47: =IF(AD47=1,1,0) -> 0 | AJ47: =IF(AD47=0,1,0) -> 0 | AL47: ='Proposte d''Acquisto'!B8 -> RICCARDO | AM47: =IF(AU47>AV47,3,IF(AU47<AV47,0,IF(AU47="","",1))) | AN47: =IF(AV47>AU47,3,IF(AV47<AU47,0,IF(AV47="","",1))) | AO47: =IF(AM47=3,1,0) -> 0 | AP47: =IF(AM47=1,1,0) -> 0 | AQ47: =IF(AM47=0,1,0) -> 0 | AR47: =IF(AN47=3,1,0) -> 0 | AS47: =IF(AN47=1,1,0) -> 0 | AT47: =IF(AN47=0,1,0) -> 0
D48: ='Proposte d''Acquisto'!B23 -> MOLINA | E48: =IF(B48>C48,3,IF(B48<C48,0,IF(B48="","",1))) | F48: =IF(C48>B48,3,IF(C48<B48,0,IF(C48="","",1))) | G48: =IF(E48=3,1,0) -> 0 | H48: =IF(E48=1,1,0) -> 0 | I48: =IF(E48=0,1,0) -> 0 | J48: =IF(F48=3,1,0) -> 0 | K48: =IF(F48=1,1,0) -> 0 | L48: =IF(F48=0,1,0) -> 0 | N48: ='Proposte d''Acquisto'!B3 -> ENRICO | O48: =IF(W48>X48,3,IF(W48<X48,0,IF(W48="","",1))) | P48: =IF(X48>W48,3,IF(X48<W48,0,IF(X48="","",1))) | Q48: =IF(O48=3,1,0) -> 0 | R48: =IF(O48=1,1,0) -> 0 | S48: =IF(O48=0,1,0) -> 0 | T48: =IF(P48=3,1,0) -> 0 | U48: =IF(P48=1,1,0) -> 0 | V48: =IF(P48=0,1,0) -> 0 | AB48: ='Proposte d''Acquisto'!B23 -> MOLINA | AC48: =IF(Z48>AA48,3,IF(Z48<AA48,0,IF(Z48="","",1))) | AD48: =IF(AA48>Z48,3,IF(AA48<Z48,0,IF(AA48="","",1))) | AE48: =IF(AC48=3,1,0) -> 0 | AF48: =IF(AC48=1,1,0) -> 0 | AG48: =IF(AC48=0,1,0) -> 0 | AH48: =IF(AD48=3,1,0) -> 0 | AI48: =IF(AD48=1,1,0) -> 0 | AJ48: =IF(AD48=0,1,0) -> 0 | AL48: ='Proposte d''Acquisto'!B3 -> ENRICO | AM48: =IF(AU48>AV48,3,IF(AU48<AV48,0,IF(AU48="","",1))) | AN48: =IF(AV48>AU48,3,IF(AV48<AU48,0,IF(AV48="","",1))) | AO48: =IF(AM48=3,1,0) -> 0 | AP48: =IF(AM48=1,1,0) -> 0 | AQ48: =IF(AM48=0,1,0) -> 0 | AR48: =IF(AN48=3,1,0) -> 0 | AS48: =IF(AN48=1,1,0) -> 0 | AT48: =IF(AN48=0,1,0) -> 0
D49: ='Proposte d''Acquisto'!B38 -> DARIO | E49: =IF(B49>C49,3,IF(B49<C49,0,IF(B49="","",1))) | F49: =IF(C49>B49,3,IF(C49<B49,0,IF(C49="","",1))) | G49: =IF(E49=3,1,0) -> 0 | H49: =IF(E49=1,1,0) -> 0 | I49: =IF(E49=0,1,0) -> 0 | J49: =IF(F49=3,1,0) -> 0 | K49: =IF(F49=1,1,0) -> 0 | L49: =IF(F49=0,1,0) -> 0 | N49: ='Proposte d''Acquisto'!B33 -> VINCENZO | O49: =IF(W49>X49,3,IF(W49<X49,0,IF(W49="","",1))) | P49: =IF(X49>W49,3,IF(X49<W49,0,IF(X49="","",1))) | Q49: =IF(O49=3,1,0) -> 0 | R49: =IF(O49=1,1,0) -> 0 | S49: =IF(O49=0,1,0) -> 0 | T49: =IF(P49=3,1,0) -> 0 | U49: =IF(P49=1,1,0) -> 0 | V49: =IF(P49=0,1,0) -> 0 | AB49: ='Proposte d''Acquisto'!B38 -> DARIO | AC49: =IF(Z49>AA49,3,IF(Z49<AA49,0,IF(Z49="","",1))) | AD49: =IF(AA49>Z49,3,IF(AA49<Z49,0,IF(AA49="","",1))) | AE49: =IF(AC49=3,1,0) -> 0 | AF49: =IF(AC49=1,1,0) -> 0 | AG49: =IF(AC49=0,1,0) -> 0 | AH49: =IF(AD49=3,1,0) -> 0 | AI49: =IF(AD49=1,1,0) -> 0 | AJ49: =IF(AD49=0,1,0) -> 0 | AL49: ='Proposte d''Acquisto'!B33 -> VINCENZO | AM49: =IF(AU49>AV49,3,IF(AU49<AV49,0,IF(AU49="","",1))) | AN49: =IF(AV49>AU49,3,IF(AV49<AU49,0,IF(AV49="","",1))) | AO49: =IF(AM49=3,1,0) -> 0 | AP49: =IF(AM49=1,1,0) -> 0 | AQ49: =IF(AM49=0,1,0) -> 0 | AR49: =IF(AN49=3,1,0) -> 0 | AS49: =IF(AN49=1,1,0) -> 0 | AT49: =IF(AN49=0,1,0) -> 0

Sheet Grafico
D9: ='Proposte d''Acquisto'!B33 -> VINCENZO | E9: ='Proposte d''Acquisto'!B23 -> MOLINA | F9: ='Proposte d''Acquisto'!B38 -> DARIO | G9: ='Proposte d''Acquisto'!B13 -> FABRIZIO | H9: ='Proposte d''Acquisto'!B18 -> DANIELE | I9: ='Proposte d''Acquisto'!B8 -> RICCARDO | J9: ='Proposte d''Acquisto'!B3 -> ENRICO | K9: ='Proposte d''Acquisto'!B28 -> EUGENIO
C10: 0 | D10: 0 | E10: 0 | F10: 0 | G10: 0 | H10: 0 | I10: 0 | J10: 0 | K10: 0
C11: 1 | D11: =SUM(CAMPIONATO!$E$7) -> 0 | E11: =SUM(CAMPIONATO!$E$6) -> 0 | F11: =SUM(CAMPIONATO!$F$5) -> 0 | G11: =SUM(CAMPIONATO!$E$5) -> 0 | H11: =SUM(CAMPIONATO!$F$7) -> 0 | I11: =SUM(CAMPIONATO!$F$4) -> 0 | J11: =SUM(CAMPIONATO!$E$4) -> 0 | K11: =SUM(CAMPIONATO!$F$6) -> 0
C12: 2 | D12: =SUM(CAMPIONATO!$E$7,CAMPIONATO!$F$12) -> 0 | E12: =SUM(CAMPIONATO!$E$6,CAMPIONATO!$F$13) -> 0 | F12: =SUM(CAMPIONATO!$F$5,CAMPIONATO!$E$13) -> 0 | G12: =SUM(CAMPIONATO!$E$5,CAMPIONATO!$E$12) -> 0 | H12: =SUM(CAMPIONATO!$F$7,CAMPIONATO!$E$14) -> 0 | I12: =SUM(CAMPIONATO!$F$4,CAMPIONATO!$E$11) -> 0 | J12: =SUM(CAMPIONATO!$E$4,CAMPIONATO!$F$14) -> 0 | K12: =SUM(CAMPIONATO!$F$6,CAMPIONATO!$F$11) -> 0
C13: 3 | D13: =SUM(CAMPIONATO!$E$7,CAMPIONATO!$F$12,CAMPIONATO!$E$20) -> 0 | E13: =SUM(CAMPIONATO!$E$6,CAMPIONATO!$F$13,CAMPIONATO!$E$18) -> 0 | F13: =SUM(CAMPIONATO!$F$5,CAMPIONATO!$E$13,CAMPIONATO!$E$19) -> 0 | G13: =SUM(CAMPIONATO!$E$5,CAMPIONATO!$E$12,CAMPIONATO!$F$18) -> 0 | H13: =SUM(CAMPIONATO!$F$7,CAMPIONATO!$E$14,CAMPIONATO!$F$19) -> 0 | I13: =SUM(CAMPIONATO!$F$4,CAMPIONATO!$E$11,CAMPIONATO!$F$20) -> 0 | J13: =SUM(CAMPIONATO!$E$4,CAMPIONATO!$F$14,CAMPIONATO!$F$21) -> 0 | K13: =SUM(CAMPIONATO!$F$6,CAMPIONATO!$F$11,CAMPIONATO!$E$21) -> 0
C14: 4 | D14: =SUM(CAMPIONATO!$E$7,CAMPIONATO!$F$12,CAMPIONATO!$E$20,CAMPIONATO!$F$25) -> 0 | E14: =SUM(CAMPIONATO!$E$6,CAMPIONATO!$F$13,CAMPIONATO!$E$18,CAMPIONATO!$F$27) -> 0 | F14: =SUM(CAMPIONATO!$F$5,CAMPIONATO!$E$13,CAMPIONATO!$E$19,CAMPIONATO!$F$28) -> 0 | G14: =SUM(CAMPIONATO!$E$5,CAMPIONATO!$E$12,CAMPIONATO!$F$18,CAMPIONATO!$F$26) -> 0 | H14: =SUM(CAMPIONATO!$F$7,CAMPIONATO!$E$14,CAMPIONATO!$F$19,CAMPIONATO!$E$27) -> 0 | I14: =SUM(CAMPIONATO!$F$4,CAMPIONATO!$E$11,CAMPIONATO!$F$20,CAMPIONATO!$E$28) -> 0 | J14: =SUM(CAMPIONATO!$E$4,CAMPIONATO!$F$14,CAMPIONATO!$F$21,CAMPIONATO!$E$25) -> 0 | K14: =SUM(CAMPIONATO!$F$6,CAMPIONATO!$F$11,CAMPIONATO!$E$21,CAMPIONATO!$E$26) -> 0
C15: 5 | D15: =SUM(CAMPIONATO!$E$7,CAMPIONATO!$F$12,CAMPIONATO!$E$20,CAMPIONATO!$F$25,CAMPIONATO!$E$35) -> 0 | E15: =SUM(CAMPIONATO!$E$6,CAMPIONATO!$F$13,CAMPIONATO!$E$18,CAMPIONATO!$F$27,CAMPIONATO!$E$33) -> 0 | F15: =SUM(CAMPIONATO!$F$5,CAMPIONATO!$E$13,CAMPIONATO!$E$19,CAMPIONATO!$F$28,CAMPIONATO!$E$34) -> 0 | G15: =SUM(CAMPIONATO!$E$5,CAMPIONATO!$E$12,CAMPIONATO!$F$18,CAMPIONATO!$F$26,CAMPIONATO!$E$32) -> 0 | H15: =SUM(CAMPIONATO!$F$7,CAMPIONATO!$E$14,CAMPIONATO!$F$19,CAMPIONATO!$E$27,CAMPIONATO!$F$32) -> 0 | I15: =SUM(CAMPIONATO!$F$4,CAMPIONATO!$E$11,CAMPIONATO!$F$20,CAMPIONATO!$E$28,CAMPIONATO!$F$33) -> 0 | J15: =SUM(CAMPIONATO!$E$4,CAMPIONATO!$F$14,CAMPIONATO!$F$21,CAMPIONATO!$E$25,CAMPIONATO!$F$34) -> 0 | K15: =SUM(CAMPIONATO!$F$6,CAMPIONATO!$F$11,CAMPIONATO!$E$21,CAMPIONATO!$E$26,CAMPIONATO!$F$35) -> 0
C16: 6 | D16: =SUM(CAMPIONATO!$E$7,CAMPIONATO!$F$12,CAMPIONATO!$E$20,CAMPIONATO!$F$25,CAMPIONATO!$E$35,CAMPIONATO!$E$41) -> 0 | E16: =SUM(CAMPIONATO!$E$6,CAMPIONATO!$F$13,CAMPIONATO!$E$18,CAMPIONATO!$F$27,CAMPIONATO!$E$33,CAMPIONATO!$F$41) -> 0 | F16: =SUM(CAMPIONATO!$F$5,CAMPIONATO!$E$13,CAMPIONATO!$E$19,CAMPIONATO!$F$28,CAMPIONATO!$E$34,CAMPIONATO!$F$42) -> 0 | G16: =SUM(CAMPIONATO!$E$5,CAMPIONATO!$E$12,CAMPIONATO!$F$18,CAMPIONATO!$F$26,CAMPIONATO!$E$32,CAMPIONATO!$F$40) -> 0 | H16: =SUM(CAMPIONATO!$F$7,CAMPIONATO!$E$14,CAMPIONATO!$F$19,CAMPIONATO!$E$27,CAMPIONATO!$F$32,CAMPIONATO!$F$39) -> 0 | I16: =SUM(CAMPIONATO!$F$4,CAMPIONATO!$E$11,CAMPIONATO!$F$20,CAMPIONATO!$E$28,CAMPIONATO!$F$33,CAMPIONATO!$E$39) -> 0 | J16: =SUM(CAMPIONATO!$E$4,CAMPIONATO!$F$14,CAMPIONATO!$F$21,CAMPIONATO!$E$25,CAMPIONATO!$F$34,CAMPIONATO!$E$40) -> 0 | K16: =SUM(CAMPIONATO!$F$6,CAMPIONATO!$F$11,CAMPIONATO!$E$21,CAMPIONATO!$E$26,CAMPIONATO!$F$35,CAMPIONATO!$E$42) -> 0
C17: 7 | D17: =SUM(CAMPIONATO!$E$7,CAMPIONATO!$F$12,CAMPIONATO!$E$20,CAMPIONATO!$F$25,CAMPIONATO!$E$35,CAMPIONATO!$E$41,CAMPIONATO!$F$49) -> 0 | E17: =SUM(CAMPIONATO!$E$6,CAMPIONATO!$F$13,CAMPIONATO!$E$18,CAMPIONATO!$F$27,CAMPIONATO!$E$33,CAMPIONATO!$F$41,CAMPIONATO!$E$48) -> 0 | F17: =SUM(CAMPIONATO!$F$5,CAMPIONATO!$E$13,CAMPIONATO!$E$19,CAMPIONATO!$F$28,CAMPIONATO!$E$34,CAMPIONATO!$F$42,CAMPIONATO!$E$49) -> 0 | G17: =SUM(CAMPIONATO!$E$5,CAMPIONATO!$E$12,CAMPIONATO!$F$18,CAMPIONATO!$F$26,CAMPIONATO!$E$32,CAMPIONATO!$F$40,CAMPIONATO!$E$47) -> 0 | H17: =SUM(CAMPIONATO!$F$7,CAMPIONATO!$E$14,CAMPIONATO!$F$19,CAMPIONATO!$E$27,CAMPIONATO!$F$32,CAMPIONATO!$F$39,CAMPIONATO!$E$46) -> 0 | I17: =SUM(CAMPIONATO!$F$4,CAMPIONATO!$E$11,CAMPIONATO!$F$20,CAMPIONATO!$E$28,CAMPIONATO!$F$33,CAMPIONATO!$E$39,CAMPIONATO!$F$47) -> 0 | J17: =SUM(CAMPIONATO!$E$4,CAMPIONATO!$F$14,CAMPIONATO!$F$21,CAMPIONATO!$E$25,CAMPIONATO!$F$34,CAMPIONATO!$E$40,CAMPIONATO!$F$48) -> 0 | K17: =SUM(CAMPIONATO!$F$6,CAMPIONATO!$F$11,CAMPIONATO!$E$21,CAMPIONATO!$E$26,CAMPIONATO!$F$35,CAMPIONATO!$E$42,CAMPIONATO!$F$46) -> 0
C18: 8 | D18: =SUM(CAMPIONATO!$E$7,CAMPIONATO!$F$12,CAMPIONATO!$E$20,CAMPIONATO!$F$25,CAMPIONATO!$E$35,CAMPIONATO!$E$41,CAMPIONATO!$F$49,CAMPIONATO!$O$7) -> 0 | E18: =SUM(CAMPIONATO!$E$6,CAMPIONATO!$F$13,CAMPIONATO!$E$18,CAMPIONATO!$F$27,CAMPIONATO!$E$33,CAMPIONATO!$F$41,CAMPIONATO!$E$48,CAMPIONATO!$O$6) -> 0 | F18: =SUM(CAMPIONATO!$F$5,CAMPIONATO!$E$13,CAMPIONATO!$E$19,CAMPIONATO!$F$28,CAMPIONATO!$E$34,CAMPIONATO!$F$42,CAMPIONATO!$E$49,CAMPIONATO!$P$5) -> 0 | G18: =SUM(CAMPIONATO!$E$5,CAMPIONATO!$E$12,CAMPIONATO!$F$18,CAMPIONATO!$F$26,CAMPIONATO!$E$32,CAMPIONATO!$F$40,CAMPIONATO!$E$47,CAMPIONATO!$O$5) -> 0 | H18: =SUM(CAMPIONATO!$F$7,CAMPIONATO!$E$14,CAMPIONATO!$F$19,CAMPIONATO!$E$27,CAMPIONATO!$F$32,CAMPIONATO!$F$39,CAMPIONATO!$E$46,CAMPIONATO!$P$7) -> 0 | I18: =SUM(CAMPIONATO!$F$4,CAMPIONATO!$E$11,CAMPIONATO!$F$20,CAMPIONATO!$E$28,CAMPIONATO!$F$33,CAMPIONATO!$E$39,CAMPIONATO!$F$47,CAMPIONATO!$P$4) -> 0 | J18: =SUM(CAMPIONATO!$E$4,CAMPIONATO!$F$14,CAMPIONATO!$F$21,CAMPIONATO!$E$25,CAMPIONATO!$F$34,CAMPIONATO!$E$40,CAMPIONATO!$F$48,CAMPIONATO!$O$4) -> 0 | K18: =SUM(CAMPIONATO!$F$6,CAMPIONATO!$F$11,CAMPIONATO!$E$21,CAMPIONATO!$E$26,CAMPIONATO!$F$35,CAMPIONATO!$E$42,CAMPIONATO!$F$46,CAMPIONATO!$P$6) -> 0
C19: 9 | D19: =SUM(CAMPIONATO!$E$7,CAMPIONATO!$F$12,CAMPIONATO!$E$20,CAMPIONATO!$F$25,CAMPIONATO!$E$35,CAMPIONATO!$E$41,CAMPIONATO!$F$49,CAMPIONATO!$O$7,CAMPIONATO!$P$12) -> 0 | E19: =SUM(CAMPIONATO!$E$6,CAMPIONATO!$F$13,CAMPIONATO!$E$18,CAMPIONATO!$F$27,CAMPIONATO!$E$33,CAMPIONATO!$F$41,CAMPIONATO!$E$48,CAMPIONATO!$O$6,CAMPIONATO!$P$13) -> 0 | F19: =SUM(CAMPIONATO!$F$5,CAMPIONATO!$E$13,CAMPIONATO!$E$19,CAMPIONATO!$F$28,CAMPIONATO!$E$34,CAMPIONATO!$F$42,CAMPIONATO!$E$49,CAMPIONATO!$P$5,CAMPIONATO!$O$13) -> 0 | G19: =SUM(CAMPIONATO!$E$5,CAMPIONATO!$E$12,CAMPIONATO!$F$18,CAMPIONATO!$F$26,CAMPIONATO!$E$32,CAMPIONATO!$F$40,CAMPIONATO!$E$47,CAMPIONATO!$O$5,CAMPIONATO!$O$12) -> 0 | H19: =SUM(CAMPIONATO!$F$7,CAMPIONATO!$E$14,CAMPIONATO!$F$19,CAMPIONATO!$E$27,CAMPIONATO!$F$32,CAMPIONATO!$F$39,CAMPIONATO!$E$46,CAMPIONATO!$P$7,CAMPIONATO!$O$14) -> 0 | I19: =SUM(CAMPIONATO!$F$4,CAMPIONATO!$E$11,CAMPIONATO!$F$20,CAMPIONATO!$E$28,CAMPIONATO!$F$33,CAMPIONATO!$E$39,CAMPIONATO!$F$47,CAMPIONATO!$P$4,CAMPIONATO!$O$11) -> 0 | J19: =SUM(CAMPIONATO!$E$4,CAMPIONATO!$F$14,CAMPIONATO!$F$21,CAMPIONATO!$E$25,CAMPIONATO!$F$34,CAMPIONATO!$E$40,CAMPIONATO!$F$48,CAMPIONATO!$O$4,CAMPIONATO!$P$14) -> 0 | K19: =SUM(CAMPIONATO!$F$6,CAMPIONATO!$F$11,CAMPIONATO!$E$21,CAMPIONATO!$E$26,CAMPIONATO!$F$35,CAMPIONATO!$E$42,CAMPIONATO!$F$46,CAMPIONATO!$P$6,CAMPIONATO!$P$11) -> 0
C20: 10 | D20: =SUM(CAMPIONATO!$E$7,CAMPIONATO!$F$12,CAMPIONATO!$E$20,CAMPIONATO!$F$25,CAMPIONATO!$E$35,CAMPIONATO!$E$41,CAMPIONATO!$F$49,CAMPIONATO!$O$7,CAMPIONATO!$P$12,CAMPIONATO!$O$20) -> 0 | E20: =SUM(CAMPIONATO!$E$6,CAMPIONATO!$F$13,CAMPIONATO!$E$18,CAMPIONATO!$F$27,CAMPIONATO!$E$33,CAMPIONATO!$F$41,CAMPIONATO!$E$48,CAMPIONATO!$O$6,CAMPIONATO!$P$13,CAMPIONATO!$O$18) -> 0 | F20: =SUM(CAMPIONATO!$F$5,CAMPIONATO!$E$13,CAMPIONATO!$E$19,CAMPIONATO!$F$28,CAMPIONATO!$E$34,CAMPIONATO!$F$42,CAMPIONATO!$E$49,CAMPIONATO!$P$5,CAMPIONATO!$O$13,CAMPIONATO!$O$19) -> 0 | G20: =SUM(CAMPIONATO!$E$5,CAMPIONATO!$E$12,CAMPIONATO!$F$18,CAMPIONATO!$F$26,CAMPIONATO!$E$32,CAMPIONATO!$F$40,CAMPIONATO!$E$47,CAMPIONATO!$O$5,CAMPIONATO!$O$12,CAMPIONATO!$P$18) -> 0 | H20: =SUM(CAMPIONATO!$F$7,CAMPIONATO!$E$14,CAMPIONATO!$F$19,CAMPIONATO!$E$27,CAMPIONATO!$F$32,CAMPIONATO!$F$39,CAMPIONATO!$E$46,CAMPIONATO!$P$7,CAMPIONATO!$O$14,CAMPIONATO!$P$19) -> 0 | I20: =SUM(CAMPIONATO!$F$4,CAMPIONATO!$E$11,CAMPIONATO!$F$20,CAMPIONATO!$E$28,CAMPIONATO!$F$33,CAMPIONATO!$E$39,CAMPIONATO!$F$47,CAMPIONATO!$P$4,CAMPIONATO!$O$11,CAMPIONATO!$P$20) -> 0 | J20: =SUM(CAMPIONATO!$E$4,CAMPIONATO!$F$14,CAMPIONATO!$F$21,CAMPIONATO!$E$25,CAMPIONATO!$F$34,CAMPIONATO!$E$40,CAMPIONATO!$F$48,CAMPIONATO!$O$4,CAMPIONATO!$P$14,CAMPIONATO!$P$21) -> 0 | K20: =SUM(CAMPIONATO!$F$6,CAMPIONATO!$F$11,CAMPIONATO!$E$21,CAMPIONATO!$E$26,CAMPIONATO!$F$35,CAMPIONATO!$E$42,CAMPIONATO!$F$46,CAMPIONATO!$P$6,CAMPIONATO!$P$11,CAMPIONATO!$O$21) -> 0
C21: 11 | D21: =SUM(CAMPIONATO!$E$7,CAMPIONATO!$F$12,CAMPIONATO!$E$20,CAMPIONATO!$F$25,CAMPIONATO!$E$35,CAMPIONATO!$E$41,CAMPIONATO!$F$49,CAMPIONATO!$O$7,CAMPIONATO!$P$12,CAMPIONATO!$O$20,CAMPIONATO!$P$25) -> 0 | E21: =SUM(CAMPIONATO!$E$6,CAMPIONATO!$F$13,CAMPIONATO!$E$18,CAMPIONATO!$F$27,CAMPIONATO!$E$33,CAMPIONATO!$F$41,CAMPIONATO!$E$48,CAMPIONATO!$O$6,CAMPIONATO!$P$13,CAMPIONATO!$O$18,CAMPIONATO!$P$27) -> 0 | F21: =SUM(CAMPIONATO!$F$5,CAMPIONATO!$E$13,CAMPIONATO!$E$19,CAMPIONATO!$F$28,CAMPIONATO!$E$34,CAMPIONATO!$F$42,CAMPIONATO!$E$49,CAMPIONATO!$P$5,CAMPIONATO!$O$13,CAMPIONATO!$O$19,CAMPIONATO!$P$28) -> 0 | G21: =SUM(CAMPIONATO!$E$5,CAMPIONATO!$E$12,CAMPIONATO!$F$18,CAMPIONATO!$F$26,CAMPIONATO!$E$32,CAMPIONATO!$F$40,CAMPIONATO!$E$47,CAMPIONATO!$O$5,CAMPIONATO!$O$12,CAMPIONATO!$P$18,CAMPIONATO!$P$26) -> 0 | H21: =SUM(CAMPIONATO!$F$7,CAMPIONATO!$E$14,CAMPIONATO!$F$19,CAMPIONATO!$E$27,CAMPIONATO!$F$32,CAMPIONATO!$F$39,CAMPIONATO!$E$46,CAMPIONATO!$P$7,CAMPIONATO!$O$14,CAMPIONATO!$P$19,CAMPIONATO!$O$27) -> 0 | I21: =SUM(CAMPIONATO!$F$4,CAMPIONATO!$E$11,CAMPIONATO!$F$20,CAMPIONATO!$E$28,CAMPIONATO!$F$33,CAMPIONATO!$E$39,CAMPIONATO!$F$47,CAMPIONATO!$P$4,CAMPIONATO!$O$11,CAMPIONATO!$P$20,CAMPIONATO!$O$28) -> 0 | J21: =SUM(CAMPIONATO!$E$4,CAMPIONATO!$F$14,CAMPIONATO!$F$21,CAMPIONATO!$E$25,CAMPIONATO!$F$34,CAMPIONATO!$E$40,CAMPIONATO!$F$48,CAMPIONATO!$O$4,CAMPIONATO!$P$14,CAMPIONATO!$P$21,CAMPIONATO!$O$25) -> 0 | K21: =SUM(CAMPIONATO!$F$6,CAMPIONATO!$F$11,CAMPIONATO!$E$21,CAMPIONATO!$E$26,CAMPIONATO!$F$35,CAMPIONATO!$E$42,CAMPIONATO!$F$46,CAMPIONATO!$P$6,CAMPIONATO!$P$11,CAMPIONATO!$O$21,CAMPIONATO!$O$26) -> 0
C22: 12 | D22: =SUM(CAMPIONATO!$E$7,CAMPIONATO!$F$12,CAMPIONATO!$E$20,CAMPIONATO!$F$25,CAMPIONATO!$E$35,CAMPIONATO!$E$41,CAMPIONATO!$F$49,CAMPIONATO!$O$7,CAMPIONATO!$P$12,CAMPIONATO!$O$20,CAMPIONATO!$P$25,CAMPIONATO!$O$35) -> 0 | E22: =SUM(CAMPIONATO!$E$6,CAMPIONATO!$F$13,CAMPIONATO!$E$18,CAMPIONATO!$F$27,CAMPIONATO!$E$33,CAMPIONATO!$F$41,CAMPIONATO!$E$48,CAMPIONATO!$O$6,CAMPIONATO!$P$13,CAMPIONATO!$O$18,CAMPIONATO!$P$27,CAMPIONATO!$O$33) -> 0 | F22: =SUM(CAMPIONATO!$F$5,CAMPIONATO!$E$13,CAMPIONATO!$E$19,CAMPIONATO!$F$28,CAMPIONATO!$E$34,CAMPIONATO!$F$42,CAMPIONATO!$E$49,CAMPIONATO!$P$5,CAMPIONATO!$O$13,CAMPIONATO!$O$19,CAMPIONATO!$P$28,CAMPIONATO!$O$34) -> 0 | G22: =SUM(CAMPIONATO!$E$5,CAMPIONATO!$E$12,CAMPIONATO!$F$18,CAMPIONATO!$F$26,CAMPIONATO!$E$32,CAMPIONATO!$F$40,CAMPIONATO!$E$47,CAMPIONATO!$O$5,CAMPIONATO!$O$12,CAMPIONATO!$P$18,CAMPIONATO!$P$26,CAMPIONATO!$O$32) -> 0 | H22: =SUM(CAMPIONATO!$F$7,CAMPIONATO!$E$14,CAMPIONATO!$F$19,CAMPIONATO!$E$27,CAMPIONATO!$F$32,CAMPIONATO!$F$39,CAMPIONATO!$E$46,CAMPIONATO!$P$7,CAMPIONATO!$O$14,CAMPIONATO!$P$19,CAMPIONATO!$O$27,CAMPIONATO!$P$32) -> 0 | I22: =SUM(CAMPIONATO!$F$4,CAMPIONATO!$E$11,CAMPIONATO!$F$20,CAMPIONATO!$E$28,CAMPIONATO!$F$33,CAMPIONATO!$E$39,CAMPIONATO!$F$47,CAMPIONATO!$P$4,CAMPIONATO!$O$11,CAMPIONATO!$P$20,CAMPIONATO!$O$28,CAMPIONATO!$P$33) -> 0 | J22: =SUM(CAMPIONATO!$E$4,CAMPIONATO!$F$14,CAMPIONATO!$F$21,CAMPIONATO!$E$25,CAMPIONATO!$F$34,CAMPIONATO!$E$40,CAMPIONATO!$F$48,CAMPIONATO!$O$4,CAMPIONATO!$P$14,CAMPIONATO!$P$21,CAMPIONATO!$O$25,CAMPIONATO!$P$34) -> 0 | K22: =SUM(CAMPIONATO!$F$6,CAMPIONATO!$F$11,CAMPIONATO!$E$21,CAMPIONATO!$E$26,CAMPIONATO!$F$35,CAMPIONATO!$E$42,CAMPIONATO!$F$46,CAMPIONATO!$P$6,CAMPIONATO!$P$11,CAMPIONATO!$O$21,CAMPIONATO!$O$26,CAMPIONATO!$P$35) -> 0
C23: 13 | D23: =SUM(CAMPIONATO!$E$7,CAMPIONATO!$F$12,CAMPIONATO!$E$20,CAMPIONATO!$F$25,CAMPIONATO!$E$35,CAMPIONATO!$E$41,CAMPIONATO!$F$49,CAMPIONATO!$O$7,CAMPIONATO!$P$12,CAMPIONATO!$O$20,CAMPIONATO!$P$25,CAMPIONATO!$O$35,CAMPIONATO!$O$41) -> 0 | E23: =SUM(CAMPIONATO!$E$6,CAMPIONATO!$F$13,CAMPIONATO!$E$18,CAMPIONATO!$F$27,CAMPIONATO!$E$33,CAMPIONATO!$F$41,CAMPIONATO!$E$48,CAMPIONATO!$O$6,CAMPIONATO!$P$13,CAMPIONATO!$O$18,CAMPIONATO!$P$27,CAMPIONATO!$O$33,CAMPIONATO!$P$41) -> 0 | F23: =SUM(CAMPIONATO!$F$5,CAMPIONATO!$E$13,CAMPIONATO!$E$19,CAMPIONATO!$F$28,CAMPIONATO!$E$34,CAMPIONATO!$F$42,CAMPIONATO!$E$49,CAMPIONATO!$P$5,CAMPIONATO!$O$13,CAMPIONATO!$O$19,CAMPIONATO!$P$28,CAMPIONATO!$O$34,CAMPIONATO!$P$42) -> 0 | G23: =SUM(CAMPIONATO!$E$5,CAMPIONATO!$E$12,CAMPIONATO!$F$18,CAMPIONATO!$F$26,CAMPIONATO!$E$32,CAMPIONATO!$F$40,CAMPIONATO!$E$47,CAMPIONATO!$O$5,CAMPIONATO!$O$12,CAMPIONATO!$P$18,CAMPIONATO!$P$26,CAMPIONATO!$O$32,CAMPIONATO!$P$40) -> 0 | H23: =SUM(CAMPIONATO!$F$7,CAMPIONATO!$E$14,CAMPIONATO!$F$19,CAMPIONATO!$E$27,CAMPIONATO!$F$32,CAMPIONATO!$F$39,CAMPIONATO!$E$46,CAMPIONATO!$P$7,CAMPIONATO!$O$14,CAMPIONATO!$P$19,CAMPIONATO!$O$27,CAMPIONATO!$P$32,CAMPIONATO!$P$39) -> 0 | I23: =SUM(CAMPIONATO!$F$4,CAMPIONATO!$E$11,CAMPIONATO!$F$20,CAMPIONATO!$E$28,CAMPIONATO!$F$33,CAMPIONATO!$E$39,CAMPIONATO!$F$47,CAMPIONATO!$P$4,CAMPIONATO!$O$11,CAMPIONATO!$P$20,CAMPIONATO!$O$28,CAMPIONATO!$P$33,CAMPIONATO!$O$39) -> 0 | J23: =SUM(CAMPIONATO!$E$4,CAMPIONATO!$F$14,CAMPIONATO!$F$21,CAMPIONATO!$E$25,CAMPIONATO!$F$34,CAMPIONATO!$E$40,CAMPIONATO!$F$48,CAMPIONATO!$O$4,CAMPIONATO!$P$14,CAMPIONATO!$P$21,CAMPIONATO!$O$25,CAMPIONATO!$P$34,CAMPIONATO!$O$40) -> 0 | K23: =SUM(CAMPIONATO!$F$6,CAMPIONATO!$F$11,CAMPIONATO!$E$21,CAMPIONATO!$E$26,CAMPIONATO!$F$35,CAMPIONATO!$E$42,CAMPIONATO!$F$46,CAMPIONATO!$P$6,CAMPIONATO!$P$11,CAMPIONATO!$O$21,CAMPIONATO!$O$26,CAMPIONATO!$P$35,CAMPIONATO!$O$42) -> 0
C24: 14 | D24: =SUM(CAMPIONATO!$E$7,CAMPIONATO!$F$12,CAMPIONATO!$E$20,CAMPIONATO!$F$25,CAMPIONATO!$E$35,CAMPIONATO!$E$41,CAMPIONATO!$F$49,CAMPIONATO!$O$7,CAMPIONATO!$P$12,CAMPIONATO!$O$20,CAMPIONATO!$P$25,CAMPIONATO!$O$35,CAMPIONATO!$O$41,CAMPIONATO!$P$49) -> 0 | E24: =SUM(CAMPIONATO!$E$6,CAMPIONATO!$F$13,CAMPIONATO!$E$18,CAMPIONATO!$F$27,CAMPIONATO!$E$33,CAMPIONATO!$F$41,CAMPIONATO!$E$48,CAMPIONATO!$O$6,CAMPIONATO!$P$13,CAMPIONATO!$O$18,CAMPIONATO!$P$27,CAMPIONATO!$O$33,CAMPIONATO!$P$41,CAMPIONATO!$O$48) -> 0 | F24: =SUM(CAMPIONATO!$F$5,CAMPIONATO!$E$13,CAMPIONATO!$E$19,CAMPIONATO!$F$28,CAMPIONATO!$E$34,CAMPIONATO!$F$42,CAMPIONATO!$E$49,CAMPIONATO!$P$5,CAMPIONATO!$O$13,CAMPIONATO!$O$19,CAMPIONATO!$P$28,CAMPIONATO!$O$34,CAMPIONATO!$P$42,CAMPIONATO!$O$49) -> 0 | G24: =SUM(CAMPIONATO!$E$5,CAMPIONATO!$E$12,CAMPIONATO!$F$18,CAMPIONATO!$F$26,CAMPIONATO!$E$32,CAMPIONATO!$F$40,CAMPIONATO!$E$47,CAMPIONATO!$O$5,CAMPIONATO!$O$12,CAMPIONATO!$P$18,CAMPIONATO!$P$26,CAMPIONATO!$O$32,CAMPIONATO!$P$40,CAMPIONATO!$O$47) -> 0 | H24: =SUM(CAMPIONATO!$F$7,CAMPIONATO!$E$14,CAMPIONATO!$F$19,CAMPIONATO!$E$27,CAMPIONATO!$F$32,CAMPIONATO!$F$39,CAMPIONATO!$E$46,CAMPIONATO!$P$7,CAMPIONATO!$O$14,CAMPIONATO!$P$19,CAMPIONATO!$O$27,CAMPIONATO!$P$32,CAMPIONATO!$P$39,CAMPIONATO!$O$46) -> 0 | I24: =SUM(CAMPIONATO!$F$4,CAMPIONATO!$E$11,CAMPIONATO!$F$20,CAMPIONATO!$E$28,CAMPIONATO!$F$33,CAMPIONATO!$E$39,CAMPIONATO!$F$47,CAMPIONATO!$P$4,CAMPIONATO!$O$11,CAMPIONATO!$P$20,CAMPIONATO!$O$28,CAMPIONATO!$P$33,CAMPIONATO!$O$39,CAMPIONATO!$P$47) -> 0 | J24: =SUM(CAMPIONATO!$E$4,CAMPIONATO!$F$14,CAMPIONATO!$F$21,CAMPIONATO!$E$25,CAMPIONATO!$F$34,CAMPIONATO!$E$40,CAMPIONATO!$F$48,CAMPIONATO!$O$4,CAMPIONATO!$P$14,CAMPIONATO!$P$21,CAMPIONATO!$O$25,CAMPIONATO!$P$34,CAMPIONATO!$O$40,CAMPIONATO!$P$48) -> 0 | K24: =SUM(CAMPIONATO!$F$6,CAMPIONATO!$F$11,CAMPIONATO!$E$21,CAMPIONATO!$E$26,CAMPIONATO!$F$35,CAMPIONATO!$E$42,CAMPIONATO!$F$46,CAMPIONATO!$P$6,CAMPIONATO!$P$11,CAMPIONATO!$O$21,CAMPIONATO!$O$26,CAMPIONATO!$P$35,CAMPIONATO!$O$42,CAMPIONATO!$P$46) -> 0
C25: 15 | D25: =SUM(CAMPIONATO!$E$7,CAMPIONATO!$F$12,CAMPIONATO!$E$20,CAMPIONATO!$F$25,CAMPIONATO!$E$35,CAMPIONATO!$E$41,CAMPIONATO!$F$49,CAMPIONATO!$O$7,CAMPIONATO!$P$12,CAMPIONATO!$O$20,CAMPIONATO!$P$25,CAMPIONATO!$O$35,CAMPIONATO!$O$41,CAMPIONATO!$P$49,CAMPIONATO!$AC$7) -> 0 | E25: =SUM(CAMPIONATO!$E$6,CAMPIONATO!$F$13,CAMPIONATO!$E$18,CAMPIONATO!$F$27,CAMPIONATO!$E$33,CAMPIONATO!$F$41,CAMPIONATO!$E$48,CAMPIONATO!$O$6,CAMPIONATO!$P$13,CAMPIONATO!$O$18,CAMPIONATO!$P$27,CAMPIONATO!$O$33,CAMPIONATO!$P$41,CAMPIONATO!$O$48,CAMPIONATO!$AC$6) -> 0 | F25: =SUM(CAMPIONATO!$F$5,CAMPIONATO!$E$13,CAMPIONATO!$E$19,CAMPIONATO!$F$28,CAMPIONATO!$E$34,CAMPIONATO!$F$42,CAMPIONATO!$E$49,CAMPIONATO!$P$5,CAMPIONATO!$O$13,CAMPIONATO!$O$19,CAMPIONATO!$P$28,CAMPIONATO!$O$34,CAMPIONATO!$P$42,CAMPIONATO!$O$49,CAMPIONATO!$AD$5) -> 0 | G25: =SUM(CAMPIONATO!$E$5,CAMPIONATO!$E$12,CAMPIONATO!$F$18,CAMPIONATO!$F$26,CAMPIONATO!$E$32,CAMPIONATO!$F$40,CAMPIONATO!$E$47,CAMPIONATO!$O$5,CAMPIONATO!$O$12,CAMPIONATO!$P$18,CAMPIONATO!$P$26,CAMPIONATO!$O$32,CAMPIONATO!$P$40,CAMPIONATO!$O$47,CAMPIONATO!$AC$5) -> 0 | H25: =SUM(CAMPIONATO!$F$7,CAMPIONATO!$E$14,CAMPIONATO!$F$19,CAMPIONATO!$E$27,CAMPIONATO!$F$32,CAMPIONATO!$F$39,CAMPIONATO!$E$46,CAMPIONATO!$P$7,CAMPIONATO!$O$14,CAMPIONATO!$P$19,CAMPIONATO!$O$27,CAMPIONATO!$P$32,CAMPIONATO!$P$39,CAMPIONATO!$O$46,CAMPIONATO!$AD$7) -> 0 | I25: =SUM(CAMPIONATO!$F$4,CAMPIONATO!$E$11,CAMPIONATO!$F$20,CAMPIONATO!$E$28,CAMPIONATO!$F$33,CAMPIONATO!$E$39,CAMPIONATO!$F$47,CAMPIONATO!$P$4,CAMPIONATO!$O$11,CAMPIONATO!$P$20,CAMPIONATO!$O$28,CAMPIONATO!$P$33,CAMPIONATO!$O$39,CAMPIONATO!$P$47,CAMPIONATO!$AD$4) -> 0 | J25: =SUM(CAMPIONATO!$E$4,CAMPIONATO!$F$14,CAMPIONATO!$F$21,CAMPIONATO!$E$25,CAMPIONATO!$F$34,CAMPIONATO!$E$40,CAMPIONATO!$F$48,CAMPIONATO!$O$4,CAMPIONATO!$P$14,CAMPIONATO!$P$21,CAMPIONATO!$O$25,CAMPIONATO!$P$34,CAMPIONATO!$O$40,CAMPIONATO!$P$48,CAMPIONATO!$AC$4) -> 0 | K25: =SUM(CAMPIONATO!$F$6,CAMPIONATO!$F$11,CAMPIONATO!$E$21,CAMPIONATO!$E$26,CAMPIONATO!$F$35,CAMPIONATO!$E$42,CAMPIONATO!$F$46,CAMPIONATO!$P$6,CAMPIONATO!$P$11,CAMPIONATO!$O$21,CAMPIONATO!$O$26,CAMPIONATO!$P$35,CAMPIONATO!$O$42,CAMPIONATO!$P$46,CAMPIONATO!$AD$6) -> 0
